Workbook

Sheet راهنما
A1: دیتاست شبیه‌سازی‌شده پارکینگ هوشمند برای ممیزی و کشف تقلب
A3: • این فایل بر اساس «سند جامع کشف تقلب، خطاها و الگوهای ناهنجاری در مدیریت پارکینگ» ساخته شده و کاملاً ساختگی (Synthetic) است؛ نام‌ها، پلاک‌ها و مبالغ واقعی نیستند.
A4: • بازه داده: 2026-09-16 06:00 تا 2026-09-30 06:00 (۱۴ روز، ۴۲ شیفت، ۸ اپراتور، ۲ گیت ورود E1/E2، ۲ گیت خروج X1/X2).
A5: • تعرفه، فرجه و آستانه‌ها در شیت «تنظیمات» هستند (آستانه‌ها از سند؛ تعرفه‌ها فرض تحلیل‌گر). با تغییر آن‌ها ستون‌های فرمولی بازمحاسبه می‌شوند.
A6: • واحد پول: تومان. تاریخ‌ها میلادی. ستون‌های آبی‌رنگ در شیت‌های کمکی ورودی/فرضی هستند.
A7: • ستون «Fraud_Scenario_Label» برچسب واقعی سناریو است (برای آموزش/ارزیابی مدل)؛ برای تست کور حذف کنید.
A8: • دو اپراتور پرخطر عمداً تعریف شده‌اند: OP-03 (برداشت نقد، ابطال پس از خروج، فرجه، پوز شخصی) و OP-06 (ویرایش پلاک، راهبند، تبانی).
A9: • شیت‌ها: تراکنش_تردد (۱۰۰۰ ردیف) | تنظیمات | تعرفه | اپراتورها (پروفایل و Z-Score) | پوزها | لیست_سفید | مغایرت_شیفت | تراز_ظرفیت | خلاصه_KPI
A11: دیکشنری ستون‌های شیت تراکنش_تردد
A12: حرف ستون | B12: عنوان فارسی | C12: نام انگلیسی | D12: منبع داده | E12: توضیح
A13: A | B13: شناسه رویداد | C13: Event_ID | D13: PMS | E13: کلید یکتای رویداد تردد
A14: B | B14: پلاک نهایی | C14: Plate | D14: ANPR/PMS | E14: پلاک نهایی ثبت‌شده در سیستم (پس از ویرایش احتمالی)
A15: C | B15: پلاک خوانده‌شده اولیه | C15: Plate_OCR_Original | D15: ANPR | E15: خروجی خام پلاک‌خوان؛ فقط در صورت ویرایش دستی پر می‌شود
A16: D | B16: مدل خودرو | C16: Vehicle_Model | D16: ANPR | E16: مدل تشخیص‌داده‌شده خودرو
A17: E | B17: رنگ | C17: Vehicle_Color | D17: ANPR | E17: رنگ خودرو
A18: F | B18: رده خودرو | C18: Vehicle_Segment | D18: ANPR | E18: اقتصادی / لوکس (برای تحلیل تمرکز اضافه‌دریافتی)
A19: G | B19: زمان ورود | C19: In_Time | D19: PMS | E19: زمان ورود (میلادی)
A20: H | B20: زمان خروج | C20: Out_Time | D20: PMS | E20: زمان خروج؛ خالی = هنوز داخل پارکینگ
A21: I | B21: مدت توقف (دقیقه) | C21: Duration | D21: محاسباتی (فرمول) | E21: فرمول: خروج − ورود (برای خودروهای داخل: تا AsOf)
A22: J | B22: گیت ورود | C22: Entry_Gate | D22: Sensor | E22: E1 / E2
A23: K | B23: گیت خروج | C23: Exit_Gate | D23: Sensor | E23: X1 / X2 (E1/E2 = خروج از گیت ورودی)
... A74: BJ | B74: برچسب سناریوی واقعی | C74: Fraud_Scenario_Label | D74: برچسب | E74: Ground truth برای آموزش/ارزیابی مدل؛ برای تست کور حذف شود

Sheet تراکنش_تردد
A1: شناسه رویداد Event_ID | B1: پلاک نهایی Plate | C1: پلاک خوانده‌شده اولیه Plate_OCR_Original | D1: مدل خودرو Vehicle_Model | E1: رنگ Vehicle_Color | F1: رده خودرو Vehicle_Segment | G1: زمان ورود In_Time | H1: زمان خروج Out_Time | I1: مدت توقف (دقیقه) Duration | J1: گیت ورود Entry_Gate | K1: گیت خروج Exit_Gate | L1: اطمینان OCR ورود ANPR_Conf_In | M1: اطمینان OCR خروج ANPR_Conf_Out | N1: ویرایش دستی پلاک Manual_Edit | O1: شناسه اپراتور Operator_ID | P1: شیفت Shift | Q1: تاریخ شیفت Shift_Date | R1: شماره فیش Ticket_No | S1: وضعیت فیش Ticket_Status | T1: زمان ابطال Void_Time | U1: پالس لوپ خروج Loop_Pulses | V1: تراکنش ثبت‌شده Recorded_Transactions | W1: باز ماندن راهبند (ثانیه) Barrier_Dwell | X1: بازکردن دستی راهبند Manual_Barrier_Open | Y1: ترتیب لوپ‌ها Loop_Sequence | Z1: نحوه پرداخت Pay_Mode | AA1: ترمینال پوز POS_Terminal_ID | AB1: کد پیگیری RRN POS_RRN | AC1: زمان تراکنش بانکی POS_Time | AD1: نوع تعرفه Tariff_Type | AE1: کد تخفیف Discount_ID | AF1: عضو لیست سفید Whitelist_Member | AG1: مبلغ محاسبه‌شده (تومان) Fare_Calc | AH1: مبلغ دریافتی (تومان) Fare_Paid | AI1: اختلاف مبلغ Fare_Diff | AJ1: انحراف ساعت گیت-سرور (ثانیه) Server_Time_Diff | AK1: قطعی دوربین (ثانیه) Camera_Drop_Sec | AL1: حالت آفلاین Offline_Mode | AM1: وضعیت سنسور جای پارک Slot_Sensor_Status | AN1: ورود قبلی ثبت‌شده Prior_Entry_Exists | AO1: تصویر ورود موجود Entry_Image_Exists | AP1: سابقه توقف همان پلاک Historical_In_Park | AQ1: تطبیق سابقه (مفقودی) Plate_History_Match | AR1: ابطال پس از خروج Flag_Void_After_Exit | AS1: پوز نامعتبر/بدون RRN Flag_POS_Invalid | AT1: اضافه‌دریافتی Flag_Overcharge | AU1: کم‌ثبتی Flag_Underpay | AV1: قطار ماشین Flag_Tailgating | AW1: باز نگه‌داشتن راهبند Flag_Barrier_Keep_Open | AX1: ویرایش پلاک با OCR بالا Flag_Manual_Edit_HighConf | AY1: خلاف جهت Flag_Wrong_Direction | AZ1: انحراف ساعت Flag_Time_Drift | BA1: معافیت غیرمجاز Flag_Exempt_NoWhitelist | BB1: تکرار بن تخفیف Flag_Discount_Reuse | BC1: رسوبی نامرئی Flag_Ghost_Occupancy | BD1: تعویض فیش رسوبی Flag_Ticket_Swap | BE1: نقض توالی Flag_Passback | BF1: مفقودی مشکوک Flag_Lost_Suspicious | BG1: قطعی دوربین Flag_Camera_Drop | BH1: امتیاز ریسک ترکیبی Risk_Score | BI1: سطح ریسک Risk_Level | BJ1: برچسب سناریوی واقعی Fraud_Scenario_Label
A2: EV-00001 | B2: 27ک970-42 | D2: وانت نیسان | E2: سفید | F2: اقتصادی | G2: 46174.977 | I2: =IF(H2="",ROUND((تنظیمات!$B$7-G2)*1440,0),ROUND((H2-G2)*1440,0)) -> 173193 | J2: E2 | L2: 0.995 | N2: خیر | R2: TK-260601-00001 | S2: داخل پارکینگ | U2: 1 | V2: 1 | W2: 6.8 | X2: خیر | Y2: عادی | AD2: عادی | AF2: =IF(COUNTIF(لیست_سفید!$A$2:$A$21,B2)>0,"بله","خیر") -> خیر | AG2: =IF(H2="","",IF(AD2="فیش مفقودی",تنظیمات!$B$6,(INT(I2/1440)*تنظیمات!$B$5+IF(MOD(I2,1440)<=تنظیمات!$B$2,0,MIN(تنظیمات!$B$5,تنظیمات!$B$3+MAX(0,ROUNDUP((MOD(I2,1440)-60)/60,0))*تنظیمات!$B$4)))*INDEX(تعرفه!$B$2:$B$7,MATCH(AD2,تعرفه!$A$2:$A$7,0)))) | AI2: =IF(AG2="","",AH2-AG2) | AJ2: 0 | AK2: 0 | AL2: خیر | AM2: خالی | AN2: بله | AO2: بله | AP2: خیر | AR2: =IF(AND(T2<>"",H2<>""),IF(AND((T2-H2)*86400>=0,(T2-H2)*86400<تنظیمات!$B$13),1,0),0) -> 0 | AS2: =IF(Z2="پوز",IF(OR(AB2="",COUNTIF(پوزها!$A$2:$A$5,AA2)=0),1,0),0) -> 0 | AT2: =IF(AI2="",0,IF(AI2>0,1,0)) -> 0 | AU2: =IF(AI2="",0,IF(AI2<0,1,0)) -> 0 | AV2: =IF(U2>V2,1,0) -> 0 | AW2: =IF(OR(W2>تنظیمات!$B$8,X2="بله"),1,0) -> 0 | AX2: =IF(AND(N2="بله",L2>تنظیمات!$B$9),1,0) -> 0 | AY2: =IF(Y2="معکوس",1,0) -> 0 | AZ2: =IF(ABS(AJ2)>تنظیمات!$B$10,1,0) -> 0 | BA2: =IF(AND(OR(AD2="رایگان/VIP",AD2="جانباز"),AF2="خیر"),1,0) -> 0 | BB2: =IF(AE2="",0,IF(COUNTIF($AE$2:$AE$1001,AE2)>1,1,0)) -> 0 | BC2: =IF(AND(H2="",I2>تنظیمات!$B$12*60,AM2="خالی"),1,0) -> 1 | BD2: =IF(AND(AP2="بله",I2<تنظیمات!$B$14,AO2="خیر"),1,0) -> 0 | BE2: =IF(AN2="خیر",1,0) -> 0 | BF2: =IF(AND(AD2="فیش مفقودی",AQ2="بله",I2>تنظیمات!$B$12*60),1,0) -> 0 | BG2: =IF(AND(AK2>تنظیمات!$B$11,AL2="بله"),1,0) -> 0 | BH2: =MIN(100,AR2*تنظیمات!$B$21+AS2*تنظیمات!$B$22+AT2*تنظیمات!$B$23+AU2*تنظیمات!$B$24+AV2*تنظیمات!$B$25+AW2*تنظیمات!$B$26+AX2*تنظیمات!$B$27+AY2*تنظیمات!$B$28+AZ2*تنظیمات!$B$29+BA2*تنظیمات!$B$30+BB2*تنظیمات!$B$31+BC2*تنظیمات!$B$32+BD2*تنظیمات!$B$33+BE2*تنظیمات!$B$34+BF2*تنظیمات!$B$35+BG2*تنظیمات!$B$36) -> 15 | BI2: =IF(BH2>=60,"بحرانی",IF(BH2>=30,"مشکوک",IF(BH2>0,"هشدار","عادی"))) -> هشدار | BJ2: خودرو رسوبی نامرئی
A3: EV-00002 | B3: 96ث484-17 | D3: تیبا 2 | E3: قرمز | F3: اقتصادی | G3: 46176.427 | I3: =IF(H3="",ROUND((تنظیمات!$B$7-G3)*1440,0),ROUND((H3-G3)*1440,0)) -> 171105 | J3: E1 | L3: 0.958 | N3: خیر | R3: TK-260603-00002 | S3: داخل پارکینگ | U3: 1 | V3: 1 | W3: 4.2 | X3: خیر | Y3: عادی | AD3: عادی | AF3: =IF(COUNTIF(لیست_سفید!$A$2:$A$21,B3)>0,"بله","خیر") -> خیر | AG3: =IF(H3="","",IF(AD3="فیش مفقودی",تنظیمات!$B$6,(INT(I3/1440)*تنظیمات!$B$5+IF(MOD(I3,1440)<=تنظیمات!$B$2,0,MIN(تنظیمات!$B$5,تنظیمات!$B$3+MAX(0,ROUNDUP((MOD(I3,1440)-60)/60,0))*تنظیمات!$B$4)))*INDEX(تعرفه!$B$2:$B$7,MATCH(AD3,تعرفه!$A$2:$A$7,0)))) | AI3: =IF(AG3="","",AH3-AG3) | AJ3: 0 | AK3: 0 | AL3: خیر | AM3: خالی | AN3: بله | AO3: بله | AP3: خیر | AR3: =IF(AND(T3<>"",H3<>""),IF(AND((T3-H3)*86400>=0,(T3-H3)*86400<تنظیمات!$B$13),1,0),0) -> 0 | AS3: =IF(Z3="پوز",IF(OR(AB3="",COUNTIF(پوزها!$A$2:$A$5,AA3)=0),1,0),0) -> 0 | AT3: =IF(AI3="",0,IF(AI3>0,1,0)) -> 0 | AU3: =IF(AI3="",0,IF(AI3<0,1,0)) -> 0 | AV3: =IF(U3>V3,1,0) -> 0 | AW3: =IF(OR(W3>تنظیمات!$B$8,X3="بله"),1,0) -> 0 | AX3: =IF(AND(N3="بله",L3>تنظیمات!$B$9),1,0) -> 0 | AY3: =IF(Y3="معکوس",1,0) -> 0 | AZ3: =IF(ABS(AJ3)>تنظیمات!$B$10,1,0) -> 0 | BA3: =IF(AND(OR(AD3="رایگان/VIP",AD3="جانباز"),AF3="خیر"),1,0) -> 0 | BB3: =IF(AE3="",0,IF(COUNTIF($AE$2:$AE$1001,AE3)>1,1,0)) -> 0 | BC3: =IF(AND(H3="",I3>تنظیمات!$B$12*60,AM3="خالی"),1,0) -> 1 | BD3: =IF(AND(AP3="بله",I3<تنظیمات!$B$14,AO3="خیر"),1,0) -> 0 | BE3: =IF(AN3="خیر",1,0) -> 0 | BF3: =IF(AND(AD3="فیش مفقودی",AQ3="بله",I3>تنظیمات!$B$12*60),1,0) -> 0 | BG3: =IF(AND(AK3>تنظیمات!$B$11,AL3="بله"),1,0) -> 0 | BH3: =MIN(100,AR3*تنظیمات!$B$21+AS3*تنظیمات!$B$22+AT3*تنظیمات!$B$23+AU3*تنظیمات!$B$24+AV3*تنظیمات!$B$25+AW3*تنظیمات!$B$26+AX3*تنظیمات!$B$27+AY3*تنظیمات!$B$28+AZ3*تنظیمات!$B$29+BA3*تنظیمات!$B$30+BB3*تنظیمات!$B$31+BC3*تنظیمات!$B$32+BD3*تنظیمات!$B$33+BE3*تنظیمات!$B$34+BF3*تنظیمات!$B$35+BG3*تنظیمات!$B$36) -> 15 | BI3: =IF(BH3>=60,"بحرانی",IF(BH3>=30,"مشکوک",IF(BH3>0,"هشدار","عادی"))) -> هشدار | BJ3: خودرو رسوبی نامرئی
A4: EV-00003 | B4: 51س539-88 | D4: کیا سراتو | E4: مشکی | F4: اقتصادی | G4: 46195.886 | I4: =IF(H4="",ROUND((تنظیمات!$B$7-G4)*1440,0),ROUND((H4-G4)*1440,0)) -> 143084 | J4: E2 | L4: 0.976 | N4: خیر | R4: TK-260622-00003 | S4: داخل پارکینگ | U4: 1 | V4: 1 | W4: 6.2 | X4: خیر | Y4: عادی | AD4: عادی | AF4: =IF(COUNTIF(لیست_سفید!$A$2:$A$21,B4)>0,"بله","خیر") -> خیر | AG4: =IF(H4="","",IF(AD4="فیش مفقودی",تنظیمات!$B$6,(INT(I4/1440)*تنظیمات!$B$5+IF(MOD(I4,1440)<=تنظیمات!$B$2,0,MIN(تنظیمات!$B$5,تنظیمات!$B$3+MAX(0,ROUNDUP((MOD(I4,1440)-60)/60,0))*تنظیمات!$B$4)))*INDEX(تعرفه!$B$2:$B$7,MATCH(AD4,تعرفه!$A$2:$A$7,0)))) | AI4: =IF(AG4="","",AH4-AG4) | AJ4: 0 | AK4: 0 | AL4: خیر | AM4: خالی | AN4: بله | AO4: بله | AP4: خیر | AR4: =IF(AND(T4<>"",H4<>""),IF(AND((T4-H4)*86400>=0,(T4-H4)*86400<تنظیمات!$B$13),1,0),0) -> 0 | AS4: =IF(Z4="پوز",IF(OR(AB4="",COUNTIF(پوزها!$A$2:$A$5,AA4)=0),1,0),0) -> 0 | AT4: =IF(AI4="",0,IF(AI4>0,1,0)) -> 0 | AU4: =IF(AI4="",0,IF(AI4<0,1,0)) -> 0 | AV4: =IF(U4>V4,1,0) -> 0 | AW4: =IF(OR(W4>تنظیمات!$B$8,X4="بله"),1,0) -> 0 | AX4: =IF(AND(N4="بله",L4>تنظیمات!$B$9),1,0) -> 0 | AY4: =IF(Y4="معکوس",1,0) -> 0 | AZ4: =IF(ABS(AJ4)>تنظیمات!$B$10,1,0) -> 0 | BA4: =IF(AND(OR(AD4="رایگان/VIP",AD4="جانباز"),AF4="خیر"),1,0) -> 0 | BB4: =IF(AE4="",0,IF(COUNTIF($AE$2:$AE$1001,AE4)>1,1,0)) -> 0 | BC4: =IF(AND(H4="",I4>تنظیمات!$B$12*60,AM4="خالی"),1,0) -> 1 | BD4: =IF(AND(AP4="بله",I4<تنظیمات!$B$14,AO4="خیر"),1,0) -> 0 | BE4: =IF(AN4="خیر",1,0) -> 0 | BF4: =IF(AND(AD4="فیش مفقودی",AQ4="بله",I4>تنظیمات!$B$12*60),1,0) -> 0 | BG4: =IF(AND(AK4>تنظیمات!$B$11,AL4="بله"),1,0) -> 0 | BH4: =MIN(100,AR4*تنظیمات!$B$21+AS4*تنظیمات!$B$22+AT4*تنظیمات!$B$23+AU4*تنظیمات!$B$24+AV4*تنظیمات!$B$25+AW4*تنظیمات!$B$26+AX4*تنظیمات!$B$27+AY4*تنظیمات!$B$28+AZ4*تنظیمات!$B$29+BA4*تنظیمات!$B$30+BB4*تنظیمات!$B$31+BC4*تنظیمات!$B$32+BD4*تنظیمات!$B$33+BE4*تنظیمات!$B$34+BF4*تنظیمات!$B$35+BG4*تنظیمات!$B$36) -> 15 | BI4: =IF(BH4>=60,"بحرانی",IF(BH4>=30,"مشکوک",IF(BH4>0,"هشدار","عادی"))) -> هشدار | BJ4: خودرو رسوبی نامرئی
A5: EV-00004 | B5: 91م191-48 | D5: کیا سراتو | E5: قرمز | F5: اقتصادی | G5: 46199.247 | I5: =IF(H5="",ROUND((تنظیمات!$B$7-G5)*1440,0),ROUND((H5-G5)*1440,0)) -> 138244 | J5: E2 | L5: 0.972 | N5: خیر | R5: TK-260626-00004 | S5: داخل پارکینگ | U5: 1 | V5: 1 | W5: 7.3 | X5: خیر | Y5: عادی | AD5: عادی | AF5: =IF(COUNTIF(لیست_سفید!$A$2:$A$21,B5)>0,"بله","خیر") -> خیر | AG5: =IF(H5="","",IF(AD5="فیش مفقودی",تنظیمات!$B$6,(INT(I5/1440)*تنظیمات!$B$5+IF(MOD(I5,1440)<=تنظیمات!$B$2,0,MIN(تنظیمات!$B$5,تنظیمات!$B$3+MAX(0,ROUNDUP((MOD(I5,1440)-60)/60,0))*تنظیمات!$B$4)))*INDEX(تعرفه!$B$2:$B$7,MATCH(AD5,تعرفه!$A$2:$A$7,0)))) | AI5: =IF(AG5="","",AH5-AG5) | AJ5: -1 | AK5: 0 | AL5: خیر | AM5: خالی | AN5: بله | AO5: بله | AP5: خیر | AR5: =IF(AND(T5<>"",H5<>""),IF(AND((T5-H5)*86400>=0,(T5-H5)*86400<تنظیمات!$B$13),1,0),0) -> 0 | AS5: =IF(Z5="پوز",IF(OR(AB5="",COUNTIF(پوزها!$A$2:$A$5,AA5)=0),1,0),0) -> 0 | AT5: =IF(AI5="",0,IF(AI5>0,1,0)) -> 0 | AU5: =IF(AI5="",0,IF(AI5<0,1,0)) -> 0 | AV5: =IF(U5>V5,1,0) -> 0 | AW5: =IF(OR(W5>تنظیمات!$B$8,X5="بله"),1,0) -> 0 | AX5: =IF(AND(N5="بله",L5>تنظیمات!$B$9),1,0) -> 0 | AY5: =IF(Y5="معکوس",1,0) -> 0 | AZ5: =IF(ABS(AJ5)>تنظیمات!$B$10,1,0) -> 0 | BA5: =IF(AND(OR(AD5="رایگان/VIP",AD5="جانباز"),AF5="خیر"),1,0) -> 0 | BB5: =IF(AE5="",0,IF(COUNTIF($AE$2:$AE$1001,AE5)>1,1,0)) -> 0 | BC5: =IF(AND(H5="",I5>تنظیمات!$B$12*60,AM5="خالی"),1,0) -> 1 | BD5: =IF(AND(AP5="بله",I5<تنظیمات!$B$14,AO5="خیر"),1,0) -> 0 | BE5: =IF(AN5="خیر",1,0) -> 0 | BF5: =IF(AND(AD5="فیش مفقودی",AQ5="بله",I5>تنظیمات!$B$12*60),1,0) -> 0 | BG5: =IF(AND(AK5>تنظیمات!$B$11,AL5="بله"),1,0) -> 0 | BH5: =MIN(100,AR5*تنظیمات!$B$21+AS5*تنظیمات!$B$22+AT5*تنظیمات!$B$23+AU5*تنظیمات!$B$24+AV5*تنظیمات!$B$25+AW5*تنظیمات!$B$26+AX5*تنظیمات!$B$27+AY5*تنظیمات!$B$28+AZ5*تنظیمات!$B$29+BA5*تنظیمات!$B$30+BB5*تنظیمات!$B$31+BC5*تنظیمات!$B$32+BD5*تنظیمات!$B$33+BE5*تنظیمات!$B$34+BF5*تنظیمات!$B$35+BG5*تنظیمات!$B$36) -> 15 | BI5: =IF(BH5>=60,"بحرانی",IF(BH5>=30,"مشکوک",IF(BH5>0,"هشدار","عادی"))) -> هشدار | BJ5: خودرو رسوبی نامرئی
A6: EV-00005 | B6: 38د432-98 | D6: بنز E200 | E6: مشکی | F6: لوکس | G6: 46202.844 | I6: =IF(H6="",ROUND((تنظیمات!$B$7-G6)*1440,0),ROUND((H6-G6)*1440,0)) -> 133065 | J6: E1 | L6: 0.931 | N6: خیر | R6: TK-260629-00005 | S6: داخل پارکینگ | U6: 1 | V6: 1 | W6: 5.6 | X6: خیر | Y6: عادی | AD6: عادی | AF6: =IF(COUNTIF(لیست_سفید!$A$2:$A$21,B6)>0,"بله","خیر") -> خیر | AG6: =IF(H6="","",IF(AD6="فیش مفقودی",تنظیمات!$B$6,(INT(I6/1440)*تنظیمات!$B$5+IF(MOD(I6,1440)<=تنظیمات!$B$2,0,MIN(تنظیمات!$B$5,تنظیمات!$B$3+MAX(0,ROUNDUP((MOD(I6,1440)-60)/60,0))*تنظیمات!$B$4)))*INDEX(تعرفه!$B$2:$B$7,MATCH(AD6,تعرفه!$A$2:$A$7,0)))) | AI6: =IF(AG6="","",AH6-AG6) | AJ6: 1 | AK6: 0 | AL6: خیر | AM6: خالی | AN6: بله | AO6: بله | AP6: خیر | AR6: =IF(AND(T6<>"",H6<>""),IF(AND((T6-H6)*86400>=0,(T6-H6)*86400<تنظیمات!$B$13),1,0),0) -> 0 | AS6: =IF(Z6="پوز",IF(OR(AB6="",COUNTIF(پوزها!$A$2:$A$5,AA6)=0),1,0),0) -> 0 | AT6: =IF(AI6="",0,IF(AI6>0,1,0)) -> 0 | AU6: =IF(AI6="",0,IF(AI6<0,1,0)) -> 0 | AV6: =IF(U6>V6,1,0) -> 0 | AW6: =IF(OR(W6>تنظیمات!$B$8,X6="بله"),1,0) -> 0 | AX6: =IF(AND(N6="بله",L6>تنظیمات!$B$9),1,0) -> 0 | AY6: =IF(Y6="معکوس",1,0) -> 0 | AZ6: =IF(ABS(AJ6)>تنظیمات!$B$10,1,0) -> 0 | BA6: =IF(AND(OR(AD6="رایگان/VIP",AD6="جانباز"),AF6="خیر"),1,0) -> 0 | BB6: =IF(AE6="",0,IF(COUNTIF($AE$2:$AE$1001,AE6)>1,1,0)) -> 0 | BC6: =IF(AND(H6="",I6>تنظیمات!$B$12*60,AM6="خالی"),1,0) -> 1 | BD6: =IF(AND(AP6="بله",I6<تنظیمات!$B$14,AO6="خیر"),1,0) -> 0 | BE6: =IF(AN6="خیر",1,0) -> 0 | BF6: =IF(AND(AD6="فیش مفقودی",AQ6="بله",I6>تنظیمات!$B$12*60),1,0) -> 0 | BG6: =IF(AND(AK6>تنظیمات!$B$11,AL6="بله"),1,0) -> 0 | BH6: =MIN(100,AR6*تنظیمات!$B$21+AS6*تنظیمات!$B$22+AT6*تنظیمات!$B$23+AU6*تنظیمات!$B$24+AV6*تنظیمات!$B$25+AW6*تنظیمات!$B$26+AX6*تنظیمات!$B$27+AY6*تنظیمات!$B$28+AZ6*تنظیمات!$B$29+BA6*تنظیمات!$B$30+BB6*تنظیمات!$B$31+BC6*تنظیمات!$B$32+BD6*تنظیمات!$B$33+BE6*تنظیمات!$B$34+BF6*تنظیمات!$B$35+BG6*تنظیمات!$B$36) -> 15 | BI6: =IF(BH6>=60,"بحرانی",IF(BH6>=30,"مشکوک",IF(BH6>0,"هشدار","عادی"))) -> هشدار | BJ6: خودرو رسوبی نامرئی
A7: EV-00006 | B7: 34ک331-98 | D7: وانت نیسان | E7: نقره‌ای | F7: اقتصادی | G7: 46204.602 | I7: =IF(H7="",ROUND((تنظیمات!$B$7-G7)*1440,0),ROUND((H7-G7)*1440,0)) -> 130533 | J7: E1 | L7: 0.927 | N7: خیر | R7: TK-260701-00006 | S7: داخل پارکینگ | U7: 1 | V7: 1 | W7: 6.2 | X7: خیر | Y7: عادی | AD7: عادی | AF7: =IF(COUNTIF(لیست_سفید!$A$2:$A$21,B7)>0,"بله","خیر") -> خیر | AG7: =IF(H7="","",IF(AD7="فیش مفقودی",تنظیمات!$B$6,(INT(I7/1440)*تنظیمات!$B$5+IF(MOD(I7,1440)<=تنظیمات!$B$2,0,MIN(تنظیمات!$B$5,تنظیمات!$B$3+MAX(0,ROUNDUP((MOD(I7,1440)-60)/60,0))*تنظیمات!$B$4)))*INDEX(تعرفه!$B$2:$B$7,MATCH(AD7,تعرفه!$A$2:$A$7,0)))) | AI7: =IF(AG7="","",AH7-AG7) | AJ7: 3 | AK7: 0 | AL7: خیر | AM7: خالی | AN7: بله | AO7: بله | AP7: خیر | AR7: =IF(AND(T7<>"",H7<>""),IF(AND((T7-H7)*86400>=0,(T7-H7)*86400<تنظیمات!$B$13),1,0),0) -> 0 | AS7: =IF(Z7="پوز",IF(OR(AB7="",COUNTIF(پوزها!$A$2:$A$5,AA7)=0),1,0),0) -> 0 | AT7: =IF(AI7="",0,IF(AI7>0,1,0)) -> 0 | AU7: =IF(AI7="",0,IF(AI7<0,1,0)) -> 0 | AV7: =IF(U7>V7,1,0) -> 0 | AW7: =IF(OR(W7>تنظیمات!$B$8,X7="بله"),1,0) -> 0 | AX7: =IF(AND(N7="بله",L7>تنظیمات!$B$9),1,0) -> 0 | AY7: =IF(Y7="معکوس",1,0) -> 0 | AZ7: =IF(ABS(AJ7)>تنظیمات!$B$10,1,0) -> 0 | BA7: =IF(AND(OR(AD7="رایگان/VIP",AD7="جانباز"),AF7="خیر"),1,0) -> 0 | BB7: =IF(AE7="",0,IF(COUNTIF($AE$2:$AE$1001,AE7)>1,1,0)) -> 0 | BC7: =IF(AND(H7="",I7>تنظیمات!$B$12*60,AM7="خالی"),1,0) -> 1 | BD7: =IF(AND(AP7="بله",I7<تنظیمات!$B$14,AO7="خیر"),1,0) -> 0 | BE7: =IF(AN7="خیر",1,0) -> 0 | BF7: =IF(AND(AD7="فیش مفقودی",AQ7="بله",I7>تنظیمات!$B$12*60),1,0) -> 0 | BG7: =IF(AND(AK7>تنظیمات!$B$11,AL7="بله"),1,0) -> 0 | BH7: =MIN(100,AR7*تنظیمات!$B$21+AS7*تنظیمات!$B$22+AT7*تنظیمات!$B$23+AU7*تنظیمات!$B$24+AV7*تنظیمات!$B$25+AW7*تنظیمات!$B$26+AX7*تنظیمات!$B$27+AY7*تنظیمات!$B$28+AZ7*تنظیمات!$B$29+BA7*تنظیمات!$B$30+BB7*تنظیمات!$B$31+BC7*تنظیمات!$B$32+BD7*تنظیمات!$B$33+BE7*تنظیمات!$B$34+BF7*تنظیمات!$B$35+BG7*تنظیمات!$B$36) -> 15 | BI7: =IF(BH7>=60,"بحرانی",IF(BH7>=30,"مشکوک",IF(BH7>0,"هشدار","عادی"))) -> هشدار | BJ7: خودرو رسوبی نامرئی
A8: EV-00007 | B8: 68س481-14 | D8: تیبا 2 | E8: قرمز | F8: اقتصادی | G8: 46204.997 | I8: =IF(H8="",ROUND((تنظیمات!$B$7-G8)*1440,0),ROUND((H8-G8)*1440,0)) -> 129965 | J8: E1 | L8: 0.885 | N8: خیر | R8: TK-260701-00007 | S8: داخل پارکینگ | U8: 1 | V8: 1 | W8: 6.2 | X8: خیر | Y8: عادی | AD8: عادی | AF8: =IF(COUNTIF(لیست_سفید!$A$2:$A$21,B8)>0,"بله","خیر") -> خیر | AG8: =IF(H8="","",IF(AD8="فیش مفقودی",تنظیمات!$B$6,(INT(I8/1440)*تنظیمات!$B$5+IF(MOD(I8,1440)<=تنظیمات!$B$2,0,MIN(تنظیمات!$B$5,تنظیمات!$B$3+MAX(0,ROUNDUP((MOD(I8,1440)-60)/60,0))*تنظیمات!$B$4)))*INDEX(تعرفه!$B$2:$B$7,MATCH(AD8,تعرفه!$A$2:$A$7,0)))) | AI8: =IF(AG8="","",AH8-AG8) | AJ8: 0 | AK8: 0 | AL8: خیر | AM8: خالی | AN8: بله | AO8: بله | AP8: خیر | AR8: =IF(AND(T8<>"",H8<>""),IF(AND((T8-H8)*86400>=0,(T8-H8)*86400<تنظیمات!$B$13),1,0),0) -> 0 | AS8: =IF(Z8="پوز",IF(OR(AB8="",COUNTIF(پوزها!$A$2:$A$5,AA8)=0),1,0),0) -> 0 | AT8: =IF(AI8="",0,IF(AI8>0,1,0)) -> 0 | AU8: =IF(AI8="",0,IF(AI8<0,1,0)) -> 0 | AV8: =IF(U8>V8,1,0) -> 0 | AW8: =IF(OR(W8>تنظیمات!$B$8,X8="بله"),1,0) -> 0 | AX8: =IF(AND(N8="بله",L8>تنظیمات!$B$9),1,0) -> 0 | AY8: =IF(Y8="معکوس",1,0) -> 0 | AZ8: =IF(ABS(AJ8)>تنظیمات!$B$10,1,0) -> 0 | BA8: =IF(AND(OR(AD8="رایگان/VIP",AD8="جانباز"),AF8="خیر"),1,0) -> 0 | BB8: =IF(AE8="",0,IF(COUNTIF($AE$2:$AE$1001,AE8)>1,1,0)) -> 0 | BC8: =IF(AND(H8="",I8>تنظیمات!$B$12*60,AM8="خالی"),1,0) -> 1 | BD8: =IF(AND(AP8="بله",I8<تنظیمات!$B$14,AO8="خیر"),1,0) -> 0 | BE8: =IF(AN8="خیر",1,0) -> 0 | BF8: =IF(AND(AD8="فیش مفقودی",AQ8="بله",I8>تنظیمات!$B$12*60),1,0) -> 0 | BG8: =IF(AND(AK8>تنظیمات!$B$11,AL8="بله"),1,0) -> 0 | BH8: =MIN(100,AR8*تنظیمات!$B$21+AS8*تنظیمات!$B$22+AT8*تنظیمات!$B$23+AU8*تنظیمات!$B$24+AV8*تنظیمات!$B$25+AW8*تنظیمات!$B$26+AX8*تنظیمات!$B$27+AY8*تنظیمات!$B$28+AZ8*تنظیمات!$B$29+BA8*تنظیمات!$B$30+BB8*تنظیمات!$B$31+BC8*تنظیمات!$B$32+BD8*تنظیمات!$B$33+BE8*تنظیمات!$B$34+BF8*تنظیمات!$B$35+BG8*تنظیمات!$B$36) -> 15 | BI8: =IF(BH8>=60,"بحرانی",IF(BH8>=30,"مشکوک",IF(BH8>0,"هشدار","عادی"))) -> هشدار | BJ8: خودرو رسوبی نامرئی
A9: EV-00008 | B9: 14ش230-26 | D9: ساینا S | E9: قرمز | F9: اقتصادی | G9: 46206.135 | I9: =IF(H9="",ROUND((تنظیمات!$B$7-G9)*1440,0),ROUND((H9-G9)*1440,0)) -> 128325 | J9: E2 | L9: 0.989 | N9: خیر | R9: TK-260703-00008 | S9: داخل پارکینگ | U9: 1 | V9: 1 | W9: 4.8 | X9: خیر | Y9: عادی | AD9: عادی | AF9: =IF(COUNTIF(لیست_سفید!$A$2:$A$21,B9)>0,"بله","خیر") -> خیر | AG9: =IF(H9="","",IF(AD9="فیش مفقودی",تنظیمات!$B$6,(INT(I9/1440)*تنظیمات!$B$5+IF(MOD(I9,1440)<=تنظیمات!$B$2,0,MIN(تنظیمات!$B$5,تنظیمات!$B$3+MAX(0,ROUNDUP((MOD(I9,1440)-60)/60,0))*تنظیمات!$B$4)))*INDEX(تعرفه!$B$2:$B$7,MATCH(AD9,تعرفه!$A$2:$A$7,0)))) | AI9: =IF(AG9="","",AH9-AG9) | AJ9: -3 | AK9: 0 | AL9: خیر | AM9: خالی | AN9: بله | AO9: بله | AP9: خیر | AR9: =IF(AND(T9<>"",H9<>""),IF(AND((T9-H9)*86400>=0,(T9-H9)*86400<تنظیمات!$B$13),1,0),0) -> 0 | AS9: =IF(Z9="پوز",IF(OR(AB9="",COUNTIF(پوزها!$A$2:$A$5,AA9)=0),1,0),0) -> 0 | AT9: =IF(AI9="",0,IF(AI9>0,1,0)) -> 0 | AU9: =IF(AI9="",0,IF(AI9<0,1,0)) -> 0 | AV9: =IF(U9>V9,1,0) -> 0 | AW9: =IF(OR(W9>تنظیمات!$B$8,X9="بله"),1,0) -> 0 | AX9: =IF(AND(N9="بله",L9>تنظیمات!$B$9),1,0) -> 0 | AY9: =IF(Y9="معکوس",1,0) -> 0 | AZ9: =IF(ABS(AJ9)>تنظیمات!$B$10,1,0) -> 0 | BA9: =IF(AND(OR(AD9="رایگان/VIP",AD9="جانباز"),AF9="خیر"),1,0) -> 0 | BB9: =IF(AE9="",0,IF(COUNTIF($AE$2:$AE$1001,AE9)>1,1,0)) -> 0 | BC9: =IF(AND(H9="",I9>تنظیمات!$B$12*60,AM9="خالی"),1,0) -> 1 | BD9: =IF(AND(AP9="بله",I9<تنظیمات!$B$14,AO9="خیر"),1,0) -> 0 | BE9: =IF(AN9="خیر",1,0) -> 0 | BF9: =IF(AND(AD9="فیش مفقودی",AQ9="بله",I9>تنظیمات!$B$12*60),1,0) -> 0 | BG9: =IF(AND(AK9>تنظیمات!$B$11,AL9="بله"),1,0) -> 0 | BH9: =MIN(100,AR9*تنظیمات!$B$21+AS9*تنظیمات!$B$22+AT9*تنظیمات!$B$23+AU9*تنظیمات!$B$24+AV9*تنظیمات!$B$25+AW9*تنظیمات!$B$26+AX9*تنظیمات!$B$27+AY9*تنظیمات!$B$28+AZ9*تنظیمات!$B$29+BA9*تنظیمات!$B$30+BB9*تنظیمات!$B$31+BC9*تنظیمات!$B$32+BD9*تنظیمات!$B$33+BE9*تنظیمات!$B$34+BF9*تنظیمات!$B$35+BG9*تنظیمات!$B$36) -> 15 | BI9: =IF(BH9>=60,"بحرانی",IF(BH9>=30,"مشکوک",IF(BH9>0,"هشدار","عادی"))) -> هشدار | BJ9: خودرو رسوبی نامرئی
A10: EV-00009 | B10: 70ه810-48 | D10: پورشه ماکان | E10: آبی | F10: لوکس | G10: 46211.756 | I10: =IF(H10="",ROUND((تنظیمات!$B$7-G10)*1440,0),ROUND((H10-G10)*1440,0)) -> 120232 | J10: E1 | L10: 0.995 | N10: خیر | R10: TK-260708-00009 | S10: داخل پارکینگ | U10: 1 | V10: 1 | W10: 5.9 | X10: خیر | Y10: عادی | AD10: عادی | AF10: =IF(COUNTIF(لیست_سفید!$A$2:$A$21,B10)>0,"بله","خیر") -> خیر | AG10: =IF(H10="","",IF(AD10="فیش مفقودی",تنظیمات!$B$6,(INT(I10/1440)*تنظیمات!$B$5+IF(MOD(I10,1440)<=تنظیمات!$B$2,0,MIN(تنظیمات!$B$5,تنظیمات!$B$3+MAX(0,ROUNDUP((MOD(I10,1440)-60)/60,0))*تنظیمات!$B$4)))*INDEX(تعرفه!$B$2:$B$7,MATCH(AD10,تعرفه!$A$2:$A$7,0)))) | AI10: =IF(AG10="","",AH10-AG10) | AJ10: 3 | AK10: 0 | AL10: خیر | AM10: خالی | AN10: بله | AO10: بله | AP10: خیر | AR10: =IF(AND(T10<>"",H10<>""),IF(AND((T10-H10)*86400>=0,(T10-H10)*86400<تنظیمات!$B$13),1,0),0) -> 0 | AS10: =IF(Z10="پوز",IF(OR(AB10="",COUNTIF(پوزها!$A$2:$A$5,AA10)=0),1,0),0) -> 0 | AT10: =IF(AI10="",0,IF(AI10>0,1,0)) -> 0 | AU10: =IF(AI10="",0,IF(AI10<0,1,0)) -> 0 | AV10: =IF(U10>V10,1,0) -> 0 | AW10: =IF(OR(W10>تنظیمات!$B$8,X10="بله"),1,0) -> 0 | AX10: =IF(AND(N10="بله",L10>تنظیمات!$B$9),1,0) -> 0 | AY10: =IF(Y10="معکوس",1,0) -> 0 | AZ10: =IF(ABS(AJ10)>تنظیمات!$B$10,1,0) -> 0 | BA10: =IF(AND(OR(AD10="رایگان/VIP",AD10="جانباز"),AF10="خیر"),1,0) -> 0 | BB10: =IF(AE10="",0,IF(COUNTIF($AE$2:$AE$1001,AE10)>1,1,0)) -> 0 | BC10: =IF(AND(H10="",I10>تنظیمات!$B$12*60,AM10="خالی"),1,0) -> 1 | BD10: =IF(AND(AP10="بله",I10<تنظیمات!$B$14,AO10="خیر"),1,0) -> 0 | BE10: =IF(AN10="خیر",1,0) -> 0 | BF10: =IF(AND(AD10="فیش مفقودی",AQ10="بله",I10>تنظیمات!$B$12*60),1,0) -> 0 | BG10: =IF(AND(AK10>تنظیمات!$B$11,AL10="بله"),1,0) -> 0 | BH10: =MIN(100,AR10*تنظیمات!$B$21+AS10*تنظیمات!$B$22+AT10*تنظیمات!$B$23+AU10*تنظیمات!$B$24+AV10*تنظیمات!$B$25+AW10*تنظیمات!$B$26+AX10*تنظیمات!$B$27+AY10*تنظیمات!$B$28+AZ10*تنظیمات!$B$29+BA10*تنظیمات!$B$30+BB10*تنظیمات!$B$31+BC10*تنظیمات!$B$32+BD10*تنظیمات!$B$33+BE10*تنظیمات!$B$34+BF10*تنظیمات!$B$35+BG10*تنظیمات!$B$36) -> 15 | BI10: =IF(BH10>=60,"بحرانی",IF(BH10>=30,"مشکوک",IF(BH10>0,"هشدار","عادی"))) -> هشدار | BJ10: خودرو رسوبی نامرئی
A11: EV-00010 | B11: 95ن210-24 | D11: کیا سراتو | E11: مشکی | F11: اقتصادی | G11: 46230.061 | I11: =IF(H11="",ROUND((تنظیمات!$B$7-G11)*1440,0),ROUND((H11-G11)*1440,0)) -> 93872 | J11: E1 | L11: 0.91 | N11: خیر | R11: TK-260727-00010 | S11: داخل پارکینگ | U11: 1 | V11: 1 | W11: 6.4 | X11: خیر | Y11: عادی | AD11: عادی | AF11: =IF(COUNTIF(لیست_سفید!$A$2:$A$21,B11)>0,"بله","خیر") -> خیر | AG11: =IF(H11="","",IF(AD11="فیش مفقودی",تنظیمات!$B$6,(INT(I11/1440)*تنظیمات!$B$5+IF(MOD(I11,1440)<=تنظیمات!$B$2,0,MIN(تنظیمات!$B$5,تنظیمات!$B$3+MAX(0,ROUNDUP((MOD(I11,1440)-60)/60,0))*تنظیمات!$B$4)))*INDEX(تعرفه!$B$2:$B$7,MATCH(AD11,تعرفه!$A$2:$A$7,0)))) | AI11: =IF(AG11="","",AH11-AG11) | AJ11: 0 | AK11: 0 | AL11: خیر | AM11: خالی | AN11: بله | AO11: بله | AP11: خیر | AR11: =IF(AND(T11<>"",H11<>""),IF(AND((T11-H11)*86400>=0,(T11-H11)*86400<تنظیمات!$B$13),1,0),0) -> 0 | AS11: =IF(Z11="پوز",IF(OR(AB11="",COUNTIF(پوزها!$A$2:$A$5,AA11)=0),1,0),0) -> 0 | AT11: =IF(AI11="",0,IF(AI11>0,1,0)) -> 0 | AU11: =IF(AI11="",0,IF(AI11<0,1,0)) -> 0 | AV11: =IF(U11>V11,1,0) -> 0 | AW11: =IF(OR(W11>تنظیمات!$B$8,X11="بله"),1,0) -> 0 | AX11: =IF(AND(N11="بله",L11>تنظیمات!$B$9),1,0) -> 0 | AY11: =IF(Y11="معکوس",1,0) -> 0 | AZ11: =IF(ABS(AJ11)>تنظیمات!$B$10,1,0) -> 0 | BA11: =IF(AND(OR(AD11="رایگان/VIP",AD11="جانباز"),AF11="خیر"),1,0) -> 0 | BB11: =IF(AE11="",0,IF(COUNTIF($AE$2:$AE$1001,AE11)>1,1,0)) -> 0 | BC11: =IF(AND(H11="",I11>تنظیمات!$B$12*60,AM11="خالی"),1,0) -> 1 | BD11: =IF(AND(AP11="بله",I11<تنظیمات!$B$14,AO11="خیر"),1,0) -> 0 | BE11: =IF(AN11="خیر",1,0) -> 0 | BF11: =IF(AND(AD11="فیش مفقودی",AQ11="بله",I11>تنظیمات!$B$12*60),1,0) -> 0 | BG11: =IF(AND(AK11>تنظیمات!$B$11,AL11="بله"),1,0) -> 0 | BH11: =MIN(100,AR11*تنظیمات!$B$21+AS11*تنظیمات!$B$22+AT11*تنظیمات!$B$23+AU11*تنظیمات!$B$24+AV11*تنظیمات!$B$25+AW11*تنظیمات!$B$26+AX11*تنظیمات!$B$27+AY11*تنظیمات!$B$28+AZ11*تنظیمات!$B$29+BA11*تنظیمات!$B$30+BB11*تنظیمات!$B$31+BC11*تنظیمات!$B$32+BD11*تنظیمات!$B$33+BE11*تنظیمات!$B$34+BF11*تنظیمات!$B$35+BG11*تنظیمات!$B$36) -> 15 | BI11: =IF(BH11>=60,"بحرانی",IF(BH11>=30,"مشکوک",IF(BH11>0,"هشدار","عادی"))) -> هشدار | BJ11: خودرو رسوبی نامرئی
A12: EV-00011 | B12: 60ب917-91 | D12: هیوندای النترا | E12: مشکی | F12: اقتصادی | G12: 46238.74 | I12: =IF(H12="",ROUND((تنظیمات!$B$7-G12)*1440,0),ROUND((H12-G12)*1440,0)) -> 81374 | J12: E1 | L12: 0.967 | N12: خیر | R12: TK-260804-00011 | S12: داخل پارکینگ | U12: 1 | V12: 1 | W12: 4.4 | X12: خیر | Y12: عادی | AD12: عادی | AF12: =IF(COUNTIF(لیست_سفید!$A$2:$A$21,B12)>0,"بله","خیر") -> خیر | AG12: =IF(H12="","",IF(AD12="فیش مفقودی",تنظیمات!$B$6,(INT(I12/1440)*تنظیمات!$B$5+IF(MOD(I12,1440)<=تنظیمات!$B$2,0,MIN(تنظیمات!$B$5,تنظیمات!$B$3+MAX(0,ROUNDUP((MOD(I12,1440)-60)/60,0))*تنظیمات!$B$4)))*INDEX(تعرفه!$B$2:$B$7,MATCH(AD12,تعرفه!$A$2:$A$7,0)))) | AI12: =IF(AG12="","",AH12-AG12) | AJ12: 1 | AK12: 0 | AL12: خیر | AM12: خالی | AN12: بله | AO12: بله | AP12: خیر | AR12: =IF(AND(T12<>"",H12<>""),IF(AND((T12-H12)*86400>=0,(T12-H12)*86400<تنظیمات!$B$13),1,0),0) -> 0 | AS12: =IF(Z12="پوز",IF(OR(AB12="",COUNTIF(پوزها!$A$2:$A$5,AA12)=0),1,0),0) -> 0 | AT12: =IF(AI12="",0,IF(AI12>0,1,0)) -> 0 | AU12: =IF(AI12="",0,IF(AI12<0,1,0)) -> 0 | AV12: =IF(U12>V12,1,0) -> 0 | AW12: =IF(OR(W12>تنظیمات!$B$8,X12="بله"),1,0) -> 0 | AX12: =IF(AND(N12="بله",L12>تنظیمات!$B$9),1,0) -> 0 | AY12: =IF(Y12="معکوس",1,0) -> 0 | AZ12: =IF(ABS(AJ12)>تنظیمات!$B$10,1,0) -> 0 | BA12: =IF(AND(OR(AD12="رایگان/VIP",AD12="جانباز"),AF12="خیر"),1,0) -> 0 | BB12: =IF(AE12="",0,IF(COUNTIF($AE$2:$AE$1001,AE12)>1,1,0)) -> 0 | BC12: =IF(AND(H12="",I12>تنظیمات!$B$12*60,AM12="خالی"),1,0) -> 1 | BD12: =IF(AND(AP12="بله",I12<تنظیمات!$B$14,AO12="خیر"),1,0) -> 0 | BE12: =IF(AN12="خیر",1,0) -> 0 | BF12: =IF(AND(AD12="فیش مفقودی",AQ12="بله",I12>تنظیمات!$B$12*60),1,0) -> 0 | BG12: =IF(AND(AK12>تنظیمات!$B$11,AL12="بله"),1,0) -> 0 | BH12: =MIN(100,AR12*تنظیمات!$B$21+AS12*تنظیمات!$B$22+AT12*تنظیمات!$B$23+AU12*تنظیمات!$B$24+AV12*تنظیمات!$B$25+AW12*تنظیمات!$B$26+AX12*تنظیمات!$B$27+AY12*تنظیمات!$B$28+AZ12*تنظیمات!$B$29+BA12*تنظیمات!$B$30+BB12*تنظیمات!$B$31+BC12*تنظیمات!$B$32+BD12*تنظیمات!$B$33+BE12*تنظیمات!$B$34+BF12*تنظیمات!$B$35+BG12*تنظیمات!$B$36) -> 15 | BI12: =IF(BH12>=60,"بحرانی",IF(BH12>=30,"مشکوک",IF(BH12>0,"هشدار","عادی"))) -> هشدار | BJ12: خودرو رسوبی نامرئی
A13: EV-00012 | B13: 71س503-77 | D13: دنا پلاس | E13: مشکی | F13: اقتصادی | G13: 46239.801 | I13: =IF(H13="",ROUND((تنظیمات!$B$7-G13)*1440,0),ROUND((H13-G13)*1440,0)) -> 79846 | J13: E1 | L13: 0.948 | N13: خیر | R13: TK-260805-00012 | S13: داخل پارکینگ | U13: 1 | V13: 1 | W13: 3.7 | X13: خیر | Y13: عادی | AD13: عادی | AF13: =IF(COUNTIF(لیست_سفید!$A$2:$A$21,B13)>0,"بله","خیر") -> خیر | AG13: =IF(H13="","",IF(AD13="فیش مفقودی",تنظیمات!$B$6,(INT(I13/1440)*تنظیمات!$B$5+IF(MOD(I13,1440)<=تنظیمات!$B$2,0,MIN(تنظیمات!$B$5,تنظیمات!$B$3+MAX(0,ROUNDUP((MOD(I13,1440)-60)/60,0))*تنظیمات!$B$4)))*INDEX(تعرفه!$B$2:$B$7,MATCH(AD13,تعرفه!$A$2:$A$7,0)))) | AI13: =IF(AG13="","",AH13-AG13) | AJ13: -1 | AK13: 0 | AL13: خیر | AM13: خالی | AN13: بله | AO13: بله | AP13: خیر | AR13: =IF(AND(T13<>"",H13<>""),IF(AND((T13-H13)*86400>=0,(T13-H13)*86400<تنظیمات!$B$13),1,0),0) -> 0 | AS13: =IF(Z13="پوز",IF(OR(AB13="",COUNTIF(پوزها!$A$2:$A$5,AA13)=0),1,0),0) -> 0 | AT13: =IF(AI13="",0,IF(AI13>0,1,0)) -> 0 | AU13: =IF(AI13="",0,IF(AI13<0,1,0)) -> 0 | AV13: =IF(U13>V13,1,0) -> 0 | AW13: =IF(OR(W13>تنظیمات!$B$8,X13="بله"),1,0) -> 0 | AX13: =IF(AND(N13="بله",L13>تنظیمات!$B$9),1,0) -> 0 | AY13: =IF(Y13="معکوس",1,0) -> 0 | AZ13: =IF(ABS(AJ13)>تنظیمات!$B$10,1,0) -> 0 | BA13: =IF(AND(OR(AD13="رایگان/VIP",AD13="جانباز"),AF13="خیر"),1,0) -> 0 | BB13: =IF(AE13="",0,IF(COUNTIF($AE$2:$AE$1001,AE13)>1,1,0)) -> 0 | BC13: =IF(AND(H13="",I13>تنظیمات!$B$12*60,AM13="خالی"),1,0) -> 1 | BD13: =IF(AND(AP13="بله",I13<تنظیمات!$B$14,AO13="خیر"),1,0) -> 0 | BE13: =IF(AN13="خیر",1,0) -> 0 | BF13: =IF(AND(AD13="فیش مفقودی",AQ13="بله",I13>تنظیمات!$B$12*60),1,0) -> 0 | BG13: =IF(AND(AK13>تنظیمات!$B$11,AL13="بله"),1,0) -> 0 | BH13: =MIN(100,AR13*تنظیمات!$B$21+AS13*تنظیمات!$B$22+AT13*تنظیمات!$B$23+AU13*تنظیمات!$B$24+AV13*تنظیمات!$B$25+AW13*تنظیمات!$B$26+AX13*تنظیمات!$B$27+AY13*تنظیمات!$B$28+AZ13*تنظیمات!$B$29+BA13*تنظیمات!$B$30+BB13*تنظیمات!$B$31+BC13*تنظیمات!$B$32+BD13*تنظیمات!$B$33+BE13*تنظیمات!$B$34+BF13*تنظیمات!$B$35+BG13*تنظیمات!$B$36) -> 15 | BI13: =IF(BH13>=60,"بحرانی",IF(BH13>=30,"مشکوک",IF(BH13>0,"هشدار","عادی"))) -> هشدار | BJ13: خودرو رسوبی نامرئی
... A16: EV-00015 | B16: 57ک206-31 | D16: تیبا 2 | E16: قرمز | F16: اقتصادی | G16: 46268.52 | I16: =IF(H16="",ROUND((تنظیمات!$B$7-G16)*1440,0),ROUND((H16-G16)*1440,0)) -> 38491 | J16: E2 | L16: 0.931 | N16: خیر | R16: TK-260903-00015 | S16: داخل پارکینگ | U16: 1 | V16: 1 | W16: 3.4 | X16: خیر | Y16: عادی | AD16: عادی | AF16: =IF(COUNTIF(لیست_سفید!$A$2:$A$21,B16)>0,"بله","خیر") -> خیر | AG16: =IF(H16="","",IF(AD16="فیش مفقودی",تنظیمات!$B$6,(INT(I16/1440)*تنظیمات!$B$5+IF(MOD(I16,1440)<=تنظیمات!$B$2,0,MIN(تنظیمات!$B$5,تنظیمات!$B$3+MAX(0,ROUNDUP((MOD(I16,1440)-60)/60,0))*تنظیمات!$B$4)))*INDEX(تعرفه!$B$2:$B$7,MATCH(AD16,تعرفه!$A$2:$A$7,0)))) | AI16: =IF(AG16="","",AH16-AG16) | AJ16: 1 | AK16: 0 | AL16: خیر | AM16: خالی | AN16: بله | AO16: بله | AP16: خیر | AR16: =IF(AND(T16<>"",H16<>""),IF(AND((T16-H16)*86400>=0,(T16-H16)*86400<تنظیمات!$B$13),1,0),0) -> 0 | AS16: =IF(Z16="پوز",IF(OR(AB16="",COUNTIF(پوزها!$A$2:$A$5,AA16)=0),1,0),0) -> 0 | AT16: =IF(AI16="",0,IF(AI16>0,1,0)) -> 0 | AU16: =IF(AI16="",0,IF(AI16<0,1,0)) -> 0 | AV16: =IF(U16>V16,1,0) -> 0 | AW16: =IF(OR(W16>تنظیمات!$B$8,X16="بله"),1,0) -> 0 | AX16: =IF(AND(N16="بله",L16>تنظیمات!$B$9),1,0) -> 0 | AY16: =IF(Y16="معکوس",1,0) -> 0 | AZ16: =IF(ABS(AJ16)>تنظیمات!$B$10,1,0) -> 0 | BA16: =IF(AND(OR(AD16="رایگان/VIP",AD16="جانباز"),AF16="خیر"),1,0) -> 0 | BB16: =IF(AE16="",0,IF(COUNTIF($AE$2:$AE$1001,AE16)>1,1,0)) -> 0 | BC16: =IF(AND(H16="",I16>تنظیمات!$B$12*60,AM16="خالی"),1,0) -> 1 | BD16: =IF(AND(AP16="بله",I16<تنظیمات!$B$14,AO16="خیر"),1,0) -> 0 | BE16: =IF(AN16="خیر",1,0) -> 0 | BF16: =IF(AND(AD16="فیش مفقودی",AQ16="بله",I16>تنظیمات!$B$12*60),1,0) -> 0 | BG16: =IF(AND(AK16>تنظیمات!$B$11,AL16="بله"),1,0) -> 0 | BH16: =MIN(100,AR16*تنظیمات!$B$21+AS16*تنظیمات!$B$22+AT16*تنظیمات!$B$23+AU16*تنظیمات!$B$24+AV16*تنظیمات!$B$25+AW16*تنظیمات!$B$26+AX16*تنظیمات!$B$27+AY16*تنظیمات!$B$28+AZ16*تنظیمات!$B$29+BA16*تنظیمات!$B$30+BB16*تنظیمات!$B$31+BC16*تنظیمات!$B$32+BD16*تنظیمات!$B$33+BE16*تنظیمات!$B$34+BF16*تنظیمات!$B$35+BG16*تنظیمات!$B$36) -> 15 | BI16: =IF(BH16>=60,"بحرانی",IF(BH16>=30,"مشکوک",IF(BH16>0,"هشدار","عادی"))) -> هشدار | BJ16: خودرو رسوبی نامرئی
A17: EV-00016 | B17: 75و597-95 | D17: هیوندای النترا | E17: مشکی | F17: اقتصادی | G17: 46278.91 | H17: 46283.504 | I17: =IF(H17="",ROUND((تنظیمات!$B$7-G17)*1440,0),ROUND((H17-G17)*1440,0)) -> 6616 | J17: E2 | K17: X1 | L17: 0.995 | M17: 0.958 | N17: خیر | O17: OP-03 | P17: صبح | Q17: 46283 | R17: TK-260913-00016 | S17: تسویه‌شده | U17: 1 | V17: 1 | W17: 4.4 | X17: خیر | Y17: عادی | Z17: نقد | AD17: فیش مفقودی | AF17: =IF(COUNTIF(لیست_سفید!$A$2:$A$21,B17)>0,"بله","خیر") -> خیر | AG17: =IF(H17="","",IF(AD17="فیش مفقودی",تنظیمات!$B$6,(INT(I17/1440)*تنظیمات!$B$5+IF(MOD(I17,1440)<=تنظیمات!$B$2,0,MIN(تنظیمات!$B$5,تنظیمات!$B$3+MAX(0,ROUNDUP((MOD(I17,1440)-60)/60,0))*تنظیمات!$B$4)))*INDEX(تعرفه!$B$2:$B$7,MATCH(AD17,تعرفه!$A$2:$A$7,0)))) -> 300000 | AH17: 300000 | AI17: =IF(AG17="","",AH17-AG17) -> 0 | AJ17: -4 | AK17: 0 | AL17: خیر | AN17: بله | AO17: بله | AP17: خیر | AQ17: بله | AR17: =IF(AND(T17<>"",H17<>""),IF(AND((T17-H17)*86400>=0,(T17-H17)*86400<تنظیمات!$B$13),1,0),0) -> 0 | AS17: =IF(Z17="پوز",IF(OR(AB17="",COUNTIF(پوزها!$A$2:$A$5,AA17)=0),1,0),0) -> 0 | AT17: =IF(AI17="",0,IF(AI17>0,1,0)) -> 0 | AU17: =IF(AI17="",0,IF(AI17<0,1,0)) -> 0 | AV17: =IF(U17>V17,1,0) -> 0 | AW17: =IF(OR(W17>تنظیمات!$B$8,X17="بله"),1,0) -> 0 | AX17: =IF(AND(N17="بله",L17>تنظیمات!$B$9),1,0) -> 0 | AY17: =IF(Y17="معکوس",1,0) -> 0 | AZ17: =IF(ABS(AJ17)>تنظیمات!$B$10,1,0) -> 0 | BA17: =IF(AND(OR(AD17="رایگان/VIP",AD17="جانباز"),AF17="خیر"),1,0) -> 0 | BB17: =IF(AE17="",0,IF(COUNTIF($AE$2:$AE$1001,AE17)>1,1,0)) -> 0 | BC17: =IF(AND(H17="",I17>تنظیمات!$B$12*60,AM17="خالی"),1,0) -> 0 | BD17: =IF(AND(AP17="بله",I17<تنظیمات!$B$14,AO17="خیر"),1,0) -> 0 | BE17: =IF(AN17="خیر",1,0) -> 0 | BF17: =IF(AND(AD17="فیش مفقودی",AQ17="بله",I17>تنظیمات!$B$12*60),1,0) -> 1 | BG17: =IF(AND(AK17>تنظیمات!$B$11,AL17="بله"),1,0) -> 0 | BH17: =MIN(100,AR17*تنظیمات!$B$21+AS17*تنظیمات!$B$22+AT17*تنظیمات!$B$23+AU17*تنظیمات!$B$24+AV17*تنظیمات!$B$25+AW17*تنظیمات!$B$26+AX17*تنظیمات!$B$27+AY17*تنظیمات!$B$28+AZ17*تنظیمات!$B$29+BA17*تنظیمات!$B$30+BB17*تنظیمات!$B$31+BC17*تنظیمات!$B$32+BD17*تنظیمات!$B$33+BE17*تنظیمات!$B$34+BF17*تنظیمات!$B$35+BG17*تنظیمات!$B$36) -> 30 | BI17: =IF(BH17>=60,"بحرانی",IF(BH17>=30,"مشکوک",IF(BH17>0,"هشدار","عادی"))) -> مشکوک | BJ17: اعلام دروغین فیش مفقودی
A18: EV-00017 | B18: 39پ762-24 | D18: هیوندای النترا | E18: نقره‌ای | F18: اقتصادی | G18: 46279.075 | H18: 46281.446 | I18: =IF(H18="",ROUND((تنظیمات!$B$7-G18)*1440,0),ROUND((H18-G18)*1440,0)) -> 3414 | J18: E2 | K18: X2 | L18: 0.898 | M18: 0.991 | N18: خیر | O18: OP-02 | P18: صبح | Q18: 46281 | R18: TK-260914-00017 | S18: تسویه‌شده | U18: 1 | V18: 1 | W18: 6 | X18: خیر | Y18: عادی | Z18: پوز | AA18: T-1002 | AB18: 759256998094 | AC18: 46281.445 | AD18: عادی | AF18: =IF(COUNTIF(لیست_سفید!$A$2:$A$21,B18)>0,"بله","خیر") -> خیر | AG18: =IF(H18="","",IF(AD18="فیش مفقودی",تنظیمات!$B$6,(INT(I18/1440)*تنظیمات!$B$5+IF(MOD(I18,1440)<=تنظیمات!$B$2,0,MIN(تنظیمات!$B$5,تنظیمات!$B$3+MAX(0,ROUNDUP((MOD(I18,1440)-60)/60,0))*تنظیمات!$B$4)))*INDEX(تعرفه!$B$2:$B$7,MATCH(AD18,تعرفه!$A$2:$A$7,0)))) -> 492000 | AH18: 492000 | AI18: =IF(AG18="","",AH18-AG18) -> 0 | AJ18: 2 | AK18: 0 | AL18: خیر | AN18: بله | AO18: بله | AP18: خیر | AR18: =IF(AND(T18<>"",H18<>""),IF(AND((T18-H18)*86400>=0,(T18-H18)*86400<تنظیمات!$B$13),1,0),0) -> 0 | AS18: =IF(Z18="پوز",IF(OR(AB18="",COUNTIF(پوزها!$A$2:$A$5,AA18)=0),1,0),0) -> 0 | AT18: =IF(AI18="",0,IF(AI18>0,1,0)) -> 0 | AU18: =IF(AI18="",0,IF(AI18<0,1,0)) -> 0 | AV18: =IF(U18>V18,1,0) -> 0 | AW18: =IF(OR(W18>تنظیمات!$B$8,X18="بله"),1,0) -> 0 | AX18: =IF(AND(N18="بله",L18>تنظیمات!$B$9),1,0) -> 0 | AY18: =IF(Y18="معکوس",1,0) -> 0 | AZ18: =IF(ABS(AJ18)>تنظیمات!$B$10,1,0) -> 0 | BA18: =IF(AND(OR(AD18="رایگان/VIP",AD18="جانباز"),AF18="خیر"),1,0) -> 0 | BB18: =IF(AE18="",0,IF(COUNTIF($AE$2:$AE$1001,AE18)>1,1,0)) -> 0 | BC18: =IF(AND(H18="",I18>تنظیمات!$B$12*60,AM18="خالی"),1,0) -> 0 | BD18: =IF(AND(AP18="بله",I18<تنظیمات!$B$14,AO18="خیر"),1,0) -> 0 | BE18: =IF(AN18="خیر",1,0) -> 0 | BF18: =IF(AND(AD18="فیش مفقودی",AQ18="بله",I18>تنظیمات!$B$12*60),1,0) -> 0 | BG18: =IF(AND(AK18>تنظیمات!$B$11,AL18="بله"),1,0) -> 0 | BH18: =MIN(100,AR18*تنظیمات!$B$21+AS18*تنظیمات!$B$22+AT18*تنظیمات!$B$23+AU18*تنظیمات!$B$24+AV18*تنظیمات!$B$25+AW18*تنظیمات!$B$26+AX18*تنظیمات!$B$27+AY18*تنظیمات!$B$28+AZ18*تنظیمات!$B$29+BA18*تنظیمات!$B$30+BB18*تنظیمات!$B$31+BC18*تنظیمات!$B$32+BD18*تنظیمات!$B$33+BE18*تنظیمات!$B$34+BF18*تنظیمات!$B$35+BG18*تنظیمات!$B$36) -> 0 | BI18: =IF(BH18>=60,"بحرانی",IF(BH18>=30,"مشکوک",IF(BH18>0,"هشدار","عادی"))) -> عادی | BJ18: عادی
A19: EV-00018 | B19: 98ج885-21 | D19: MVM X22 | E19: مشکی | F19: اقتصادی | G19: 46279.52 | H19: 46281.598 | I19: =IF(H19="",ROUND((تنظیمات!$B$7-G19)*1440,0),ROUND((H19-G19)*1440,0)) -> 2992 | J19: E2 | K19: X2 | L19: 0.889 | M19: 0.954 | N19: خیر | O19: OP-04 | P19: عصر | Q19: 46281 | R19: TK-260914-00018 | S19: تسویه‌شده | U19: 1 | V19: 1 | W19: 4.7 | X19: خیر | Y19: عادی | Z19: پوز | AA19: T-1002 | AB19: 723102788396 | AC19: 46281.598 | AD19: عادی | AF19: =IF(COUNTIF(لیست_سفید!$A$2:$A$21,B19)>0,"بله","خیر") -> خیر | AG19: =IF(H19="","",IF(AD19="فیش مفقودی",تنظیمات!$B$6,(INT(I19/1440)*تنظیمات!$B$5+IF(MOD(I19,1440)<=تنظیمات!$B$2,0,MIN(تنظیمات!$B$5,تنظیمات!$B$3+MAX(0,ROUNDUP((MOD(I19,1440)-60)/60,0))*تنظیمات!$B$4)))*INDEX(تعرفه!$B$2:$B$7,MATCH(AD19,تعرفه!$A$2:$A$7,0)))) -> 394000 | AH19: 394000 | AI19: =IF(AG19="","",AH19-AG19) -> 0 | AJ19: 1 | AK19: 0 | AL19: خیر | AN19: بله | AO19: بله | AP19: خیر | AR19: =IF(AND(T19<>"",H19<>""),IF(AND((T19-H19)*86400>=0,(T19-H19)*86400<تنظیمات!$B$13),1,0),0) -> 0 | AS19: =IF(Z19="پوز",IF(OR(AB19="",COUNTIF(پوزها!$A$2:$A$5,AA19)=0),1,0),0) -> 0 | AT19: =IF(AI19="",0,IF(AI19>0,1,0)) -> 0 | AU19: =IF(AI19="",0,IF(AI19<0,1,0)) -> 0 | AV19: =IF(U19>V19,1,0) -> 0 | AW19: =IF(OR(W19>تنظیمات!$B$8,X19="بله"),1,0) -> 0 | AX19: =IF(AND(N19="بله",L19>تنظیمات!$B$9),1,0) -> 0 | AY19: =IF(Y19="معکوس",1,0) -> 0 | AZ19: =IF(ABS(AJ19)>تنظیمات!$B$10,1,0) -> 0 | BA19: =IF(AND(OR(AD19="رایگان/VIP",AD19="جانباز"),AF19="خیر"),1,0) -> 0 | BB19: =IF(AE19="",0,IF(COUNTIF($AE$2:$AE$1001,AE19)>1,1,0)) -> 0 | BC19: =IF(AND(H19="",I19>تنظیمات!$B$12*60,AM19="خالی"),1,0) -> 0 | BD19: =IF(AND(AP19="بله",I19<تنظیمات!$B$14,AO19="خیر"),1,0) -> 0 | BE19: =IF(AN19="خیر",1,0) -> 0 | BF19: =IF(AND(AD19="فیش مفقودی",AQ19="بله",I19>تنظیمات!$B$12*60),1,0) -> 0 | BG19: =IF(AND(AK19>تنظیمات!$B$11,AL19="بله"),1,0) -> 0 | BH19: =MIN(100,AR19*تنظیمات!$B$21+AS19*تنظیمات!$B$22+AT19*تنظیمات!$B$23+AU19*تنظیمات!$B$24+AV19*تنظیمات!$B$25+AW19*تنظیمات!$B$26+AX19*تنظیمات!$B$27+AY19*تنظیمات!$B$28+AZ19*تنظیمات!$B$29+BA19*تنظیمات!$B$30+BB19*تنظیمات!$B$31+BC19*تنظیمات!$B$32+BD19*تنظیمات!$B$33+BE19*تنظیمات!$B$34+BF19*تنظیمات!$B$35+BG19*تنظیمات!$B$36) -> 0 | BI19: =IF(BH19>=60,"بحرانی",IF(BH19>=30,"مشکوک",IF(BH19>0,"هشدار","عادی"))) -> عادی | BJ19: عادی
A20: EV-00019 | B20: 16ق353-72 | D20: تیبا 2 | E20: قرمز | F20: اقتصادی | G20: 46280.718 | H20: 46282.635 | I20: =IF(H20="",ROUND((تنظیمات!$B$7-G20)*1440,0),ROUND((H20-G20)*1440,0)) -> 2761 | J20: E2 | K20: X1 | L20: 0.995 | M20: 0.995 | N20: خیر | O20: OP-08 | P20: عصر | Q20: 46282 | R20: TK-260915-00019 | S20: تسویه‌شده | U20: 1 | V20: 1 | W20: 7.7 | X20: خیر | Y20: عادی | Z20: پوز | AA20: T-1001 | AB20: 481946515489 | AC20: 46282.634 | AD20: عادی | AF20: =IF(COUNTIF(لیست_سفید!$A$2:$A$21,B20)>0,"بله","خیر") -> خیر | AG20: =IF(H20="","",IF(AD20="فیش مفقودی",تنظیمات!$B$6,(INT(I20/1440)*تنظیمات!$B$5+IF(MOD(I20,1440)<=تنظیمات!$B$2,0,MIN(تنظیمات!$B$5,تنظیمات!$B$3+MAX(0,ROUNDUP((MOD(I20,1440)-60)/60,0))*تنظیمات!$B$4)))*INDEX(تعرفه!$B$2:$B$7,MATCH(AD20,تعرفه!$A$2:$A$7,0)))) -> 360000 | AH20: 360000 | AI20: =IF(AG20="","",AH20-AG20) -> 0 | AJ20: 0 | AK20: 0 | AL20: خیر | AN20: بله | AO20: بله | AP20: خیر | AR20: =IF(AND(T20<>"",H20<>""),IF(AND((T20-H20)*86400>=0,(T20-H20)*86400<تنظیمات!$B$13),1,0),0) -> 0 | AS20: =IF(Z20="پوز",IF(OR(AB20="",COUNTIF(پوزها!$A$2:$A$5,AA20)=0),1,0),0) -> 0 | AT20: =IF(AI20="",0,IF(AI20>0,1,0)) -> 0 | AU20: =IF(AI20="",0,IF(AI20<0,1,0)) -> 0 | AV20: =IF(U20>V20,1,0) -> 0 | AW20: =IF(OR(W20>تنظیمات!$B$8,X20="بله"),1,0) -> 0 | AX20: =IF(AND(N20="بله",L20>تنظیمات!$B$9),1,0) -> 0 | AY20: =IF(Y20="معکوس",1,0) -> 0 | AZ20: =IF(ABS(AJ20)>تنظیمات!$B$10,1,0) -> 0 | BA20: =IF(AND(OR(AD20="رایگان/VIP",AD20="جانباز"),AF20="خیر"),1,0) -> 0 | BB20: =IF(AE20="",0,IF(COUNTIF($AE$2:$AE$1001,AE20)>1,1,0)) -> 0 | BC20: =IF(AND(H20="",I20>تنظیمات!$B$12*60,AM20="خالی"),1,0) -> 0 | BD20: =IF(AND(AP20="بله",I20<تنظیمات!$B$14,AO20="خیر"),1,0) -> 0 | BE20: =IF(AN20="خیر",1,0) -> 0 | BF20: =IF(AND(AD20="فیش مفقودی",AQ20="بله",I20>تنظیمات!$B$12*60),1,0) -> 0 | BG20: =IF(AND(AK20>تنظیمات!$B$11,AL20="بله"),1,0) -> 0 | BH20: =MIN(100,AR20*تنظیمات!$B$21+AS20*تنظیمات!$B$22+AT20*تنظیمات!$B$23+AU20*تنظیمات!$B$24+AV20*تنظیمات!$B$25+AW20*تنظیمات!$B$26+AX20*تنظیمات!$B$27+AY20*تنظیمات!$B$28+AZ20*تنظیمات!$B$29+BA20*تنظیمات!$B$30+BB20*تنظیمات!$B$31+BC20*تنظیمات!$B$32+BD20*تنظیمات!$B$33+BE20*تنظیمات!$B$34+BF20*تنظیمات!$B$35+BG20*تنظیمات!$B$36) -> 0 | BI20: =IF(BH20>=60,"بحرانی",IF(BH20>=30,"مشکوک",IF(BH20>0,"هشدار","عادی"))) -> عادی | BJ20: عادی
A21: EV-00020 | B21: 72گ570-16 | D21: موتورسیکلت | E21: نقره‌ای | F21: اقتصادی | G21: 46281.038 | H21: 46281.54 | I21: =IF(H21="",ROUND((تنظیمات!$B$7-G21)*1440,0),ROUND((H21-G21)*1440,0)) -> 722 | J21: E2 | K21: X2 | L21: 0.928 | M21: 0.918 | N21: خیر | O21: OP-02 | P21: صبح | Q21: 46281 | R21: TK-260916-00020 | S21: تسویه‌شده | U21: 1 | V21: 1 | W21: 3.2 | X21: خیر | Y21: عادی | Z21: پوز | AA21: T-1002 | AB21: 456711973226 | AC21: 46281.539 | AD21: فیش مفقودی | AF21: =IF(COUNTIF(لیست_سفید!$A$2:$A$21,B21)>0,"بله","خیر") -> خیر | AG21: =IF(H21="","",IF(AD21="فیش مفقودی",تنظیمات!$B$6,(INT(I21/1440)*تنظیمات!$B$5+IF(MOD(I21,1440)<=تنظیمات!$B$2,0,MIN(تنظیمات!$B$5,تنظیمات!$B$3+MAX(0,ROUNDUP((MOD(I21,1440)-60)/60,0))*تنظیمات!$B$4)))*INDEX(تعرفه!$B$2:$B$7,MATCH(AD21,تعرفه!$A$2:$A$7,0)))) -> 300000 | AH21: 300000 | AI21: =IF(AG21="","",AH21-AG21) -> 0 | AJ21: 1 | AK21: 0 | AL21: خیر | AN21: بله | AO21: بله | AP21: خیر | AQ21: بله | AR21: =IF(AND(T21<>"",H21<>""),IF(AND((T21-H21)*86400>=0,(T21-H21)*86400<تنظیمات!$B$13),1,0),0) -> 0 | AS21: =IF(Z21="پوز",IF(OR(AB21="",COUNTIF(پوزها!$A$2:$A$5,AA21)=0),1,0),0) -> 0 | AT21: =IF(AI21="",0,IF(AI21>0,1,0)) -> 0 | AU21: =IF(AI21="",0,IF(AI21<0,1,0)) -> 0 | AV21: =IF(U21>V21,1,0) -> 0 | AW21: =IF(OR(W21>تنظیمات!$B$8,X21="بله"),1,0) -> 0 | AX21: =IF(AND(N21="بله",L21>تنظیمات!$B$9),1,0) -> 0 | AY21: =IF(Y21="معکوس",1,0) -> 0 | AZ21: =IF(ABS(AJ21)>تنظیمات!$B$10,1,0) -> 0 | BA21: =IF(AND(OR(AD21="رایگان/VIP",AD21="جانباز"),AF21="خیر"),1,0) -> 0 | BB21: =IF(AE21="",0,IF(COUNTIF($AE$2:$AE$1001,AE21)>1,1,0)) -> 0 | BC21: =IF(AND(H21="",I21>تنظیمات!$B$12*60,AM21="خالی"),1,0) -> 0 | BD21: =IF(AND(AP21="بله",I21<تنظیمات!$B$14,AO21="خیر"),1,0) -> 0 | BE21: =IF(AN21="خیر",1,0) -> 0 | BF21: =IF(AND(AD21="فیش مفقودی",AQ21="بله",I21>تنظیمات!$B$12*60),1,0) -> 0 | BG21: =IF(AND(AK21>تنظیمات!$B$11,AL21="بله"),1,0) -> 0 | BH21: =MIN(100,AR21*تنظیمات!$B$21+AS21*تنظیمات!$B$22+AT21*تنظیمات!$B$23+AU21*تنظیمات!$B$24+AV21*تنظیمات!$B$25+AW21*تنظیمات!$B$26+AX21*تنظیمات!$B$27+AY21*تنظیمات!$B$28+AZ21*تنظیمات!$B$29+BA21*تنظیمات!$B$30+BB21*تنظیمات!$B$31+BC21*تنظیمات!$B$32+BD21*تنظیمات!$B$33+BE21*تنظیمات!$B$34+BF21*تنظیمات!$B$35+BG21*تنظیمات!$B$36) -> 0 | BI21: =IF(BH21>=60,"بحرانی",IF(BH21>=30,"مشکوک",IF(BH21>0,"هشدار","عادی"))) -> عادی | BJ21: عادی
A22: EV-00021 | B22: 66ا743-19 | D22: MVM X22 | E22: قرمز | F22: اقتصادی | G22: 46281.041 | H22: 46281.436 | I22: =IF(H22="",ROUND((تنظیمات!$B$7-G22)*1440,0),ROUND((H22-G22)*1440,0)) -> 569 | J22: E2 | K22: X2 | L22: 0.969 | M22: 0.978 | N22: خیر | O22: OP-02 | P22: صبح | Q22: 46281 | R22: TK-260916-00021 | S22: تسویه‌شده | U22: 1 | V22: 1 | W22: 6.4 | X22: خیر | Y22: عادی | Z22: پوز | AA22: T-1002 | AB22: 753567644091 | AC22: 46281.436 | AD22: عادی | AF22: =IF(COUNTIF(لیست_سفید!$A$2:$A$21,B22)>0,"بله","خیر") -> خیر | AG22: =IF(H22="","",IF(AD22="فیش مفقودی",تنظیمات!$B$6,(INT(I22/1440)*تنظیمات!$B$5+IF(MOD(I22,1440)<=تنظیمات!$B$2,0,MIN(تنظیمات!$B$5,تنظیمات!$B$3+MAX(0,ROUNDUP((MOD(I22,1440)-60)/60,0))*تنظیمات!$B$4)))*INDEX(تعرفه!$B$2:$B$7,MATCH(AD22,تعرفه!$A$2:$A$7,0)))) -> 146000 | AH22: 146000 | AI22: =IF(AG22="","",AH22-AG22) -> 0 | AJ22: 0 | AK22: 0 | AL22: خیر | AN22: بله | AO22: بله | AP22: خیر | AR22: =IF(AND(T22<>"",H22<>""),IF(AND((T22-H22)*86400>=0,(T22-H22)*86400<تنظیمات!$B$13),1,0),0) -> 0 | AS22: =IF(Z22="پوز",IF(OR(AB22="",COUNTIF(پوزها!$A$2:$A$5,AA22)=0),1,0),0) -> 0 | AT22: =IF(AI22="",0,IF(AI22>0,1,0)) -> 0 | AU22: =IF(AI22="",0,IF(AI22<0,1,0)) -> 0 | AV22: =IF(U22>V22,1,0) -> 0 | AW22: =IF(OR(W22>تنظیمات!$B$8,X22="بله"),1,0) -> 0 | AX22: =IF(AND(N22="بله",L22>تنظیمات!$B$9),1,0) -> 0 | AY22: =IF(Y22="معکوس",1,0) -> 0 | AZ22: =IF(ABS(AJ22)>تنظیمات!$B$10,1,0) -> 0 | BA22: =IF(AND(OR(AD22="رایگان/VIP",AD22="جانباز"),AF22="خیر"),1,0) -> 0 | BB22: =IF(AE22="",0,IF(COUNTIF($AE$2:$AE$1001,AE22)>1,1,0)) -> 0 | BC22: =IF(AND(H22="",I22>تنظیمات!$B$12*60,AM22="خالی"),1,0) -> 0 | BD22: =IF(AND(AP22="بله",I22<تنظیمات!$B$14,AO22="خیر"),1,0) -> 0 | BE22: =IF(AN22="خیر",1,0) -> 0 | BF22: =IF(AND(AD22="فیش مفقودی",AQ22="بله",I22>تنظیمات!$B$12*60),1,0) -> 0 | BG22: =IF(AND(AK22>تنظیمات!$B$11,AL22="بله"),1,0) -> 0 | BH22: =MIN(100,AR22*تنظیمات!$B$21+AS22*تنظیمات!$B$22+AT22*تنظیمات!$B$23+AU22*تنظیمات!$B$24+AV22*تنظیمات!$B$25+AW22*تنظیمات!$B$26+AX22*تنظیمات!$B$27+AY22*تنظیمات!$B$28+AZ22*تنظیمات!$B$29+BA22*تنظیمات!$B$30+BB22*تنظیمات!$B$31+BC22*تنظیمات!$B$32+BD22*تنظیمات!$B$33+BE22*تنظیمات!$B$34+BF22*تنظیمات!$B$35+BG22*تنظیمات!$B$36) -> 0 | BI22: =IF(BH22>=60,"بحرانی",IF(BH22>=30,"مشکوک",IF(BH22>0,"هشدار","عادی"))) -> عادی | BJ22: عادی
A23: EV-00022 | B23: 21ج756-25 | D23: لکسوس RX | E23: قرمز | F23: لوکس | G23: 46281.066 | H23: 46281.409 | I23: =IF(H23="",ROUND((تنظیمات!$B$7-G23)*1440,0),ROUND((H23-G23)*1440,0)) -> 495 | J23: E2 | K23: X1 | L23: 0.905 | M23: 0.971 | N23: خیر | O23: OP-01 | P23: صبح | Q23: 46281 | R23: TK-260916-00022 | S23: تسویه‌شده | U23: 1 | V23: 1 | W23: 3.5 | X23: خیر | Y23: عادی | Z23: اشتراک | AD23: اشتراک ماهانه | AF23: =IF(COUNTIF(لیست_سفید!$A$2:$A$21,B23)>0,"بله","خیر") -> خیر | AG23: =IF(H23="","",IF(AD23="فیش مفقودی",تنظیمات!$B$6,(INT(I23/1440)*تنظیمات!$B$5+IF(MOD(I23,1440)<=تنظیمات!$B$2,0,MIN(تنظیمات!$B$5,تنظیمات!$B$3+MAX(0,ROUNDUP((MOD(I23,1440)-60)/60,0))*تنظیمات!$B$4)))*INDEX(تعرفه!$B$2:$B$7,MATCH(AD23,تعرفه!$A$2:$A$7,0)))) -> 0 | AH23: 0 | AI23: =IF(AG23="","",AH23-AG23) -> 0 | AJ23: 1 | AK23: 0 | AL23: خیر | AN23: بله | AO23: بله | AP23: خیر | AR23: =IF(AND(T23<>"",H23<>""),IF(AND((T23-H23)*86400>=0,(T23-H23)*86400<تنظیمات!$B$13),1,0),0) -> 0 | AS23: =IF(Z23="پوز",IF(OR(AB23="",COUNTIF(پوزها!$A$2:$A$5,AA23)=0),1,0),0) -> 0 | AT23: =IF(AI23="",0,IF(AI23>0,1,0)) -> 0 | AU23: =IF(AI23="",0,IF(AI23<0,1,0)) -> 0 | AV23: =IF(U23>V23,1,0) -> 0 | AW23: =IF(OR(W23>تنظیمات!$B$8,X23="بله"),1,0) -> 0 | AX23: =IF(AND(N23="بله",L23>تنظیمات!$B$9),1,0) -> 0 | AY23: =IF(Y23="معکوس",1,0) -> 0 | AZ23: =IF(ABS(AJ23)>تنظیمات!$B$10,1,0) -> 0 | BA23: =IF(AND(OR(AD23="رایگان/VIP",AD23="جانباز"),AF23="خیر"),1,0) -> 0 | BB23: =IF(AE23="",0,IF(COUNTIF($AE$2:$AE$1001,AE23)>1,1,0)) -> 0 | BC23: =IF(AND(H23="",I23>تنظیمات!$B$12*60,AM23="خالی"),1,0) -> 0 | BD23: =IF(AND(AP23="بله",I23<تنظیمات!$B$14,AO23="خیر"),1,0) -> 0 | BE23: =IF(AN23="خیر",1,0) -> 0 | BF23: =IF(AND(AD23="فیش مفقودی",AQ23="بله",I23>تنظیمات!$B$12*60),1,0) -> 0 | BG23: =IF(AND(AK23>تنظیمات!$B$11,AL23="بله"),1,0) -> 0 | BH23: =MIN(100,AR23*تنظیمات!$B$21+AS23*تنظیمات!$B$22+AT23*تنظیمات!$B$23+AU23*تنظیمات!$B$24+AV23*تنظیمات!$B$25+AW23*تنظیمات!$B$26+AX23*تنظیمات!$B$27+AY23*تنظیمات!$B$28+AZ23*تنظیمات!$B$29+BA23*تنظیمات!$B$30+BB23*تنظیمات!$B$31+BC23*تنظیمات!$B$32+BD23*تنظیمات!$B$33+BE23*تنظیمات!$B$34+BF23*تنظیمات!$B$35+BG23*تنظیمات!$B$36) -> 0 | BI23: =IF(BH23>=60,"بحرانی",IF(BH23>=30,"مشکوک",IF(BH23>0,"هشدار","عادی"))) -> عادی | BJ23: عادی
A24: EV-00023 | B24: 60ط464-23 | D24: وانت نیسان | E24: آبی | F24: اقتصادی | G24: 46281.104 | H24: 46281.504 | I24: =IF(H24="",ROUND((تنظیمات!$B$7-G24)*1440,0),ROUND((H24-G24)*1440,0)) -> 576 | J24: E1 | K24: X2 | L24: 0.991 | M24: 0.891 | N24: خیر | O24: OP-02 | P24: صبح | Q24: 46281 | R24: TK-260916-00023 | S24: تسویه‌شده | U24: 1 | V24: 1 | W24: 6.8 | X24: خیر | Y24: عادی | Z24: اشتراک | AD24: اشتراک ماهانه | AF24: =IF(COUNTIF(لیست_سفید!$A$2:$A$21,B24)>0,"بله","خیر") -> خیر | AG24: =IF(H24="","",IF(AD24="فیش مفقودی",تنظیمات!$B$6,(INT(I24/1440)*تنظیمات!$B$5+IF(MOD(I24,1440)<=تنظیمات!$B$2,0,MIN(تنظیمات!$B$5,تنظیمات!$B$3+MAX(0,ROUNDUP((MOD(I24,1440)-60)/60,0))*تنظیمات!$B$4)))*INDEX(تعرفه!$B$2:$B$7,MATCH(AD24,تعرفه!$A$2:$A$7,0)))) -> 0 | AH24: 0 | AI24: =IF(AG24="","",AH24-AG24) -> 0 | AJ24: -2 | AK24: 76 | AL24: خیر | AN24: بله | AO24: بله | AP24: خیر | AR24: =IF(AND(T24<>"",H24<>""),IF(AND((T24-H24)*86400>=0,(T24-H24)*86400<تنظیمات!$B$13),1,0),0) -> 0 | AS24: =IF(Z24="پوز",IF(OR(AB24="",COUNTIF(پوزها!$A$2:$A$5,AA24)=0),1,0),0) -> 0 | AT24: =IF(AI24="",0,IF(AI24>0,1,0)) -> 0 | AU24: =IF(AI24="",0,IF(AI24<0,1,0)) -> 0 | AV24: =IF(U24>V24,1,0) -> 0 | AW24: =IF(OR(W24>تنظیمات!$B$8,X24="بله"),1,0) -> 0 | AX24: =IF(AND(N24="بله",L24>تنظیمات!$B$9),1,0) -> 0 | AY24: =IF(Y24="معکوس",1,0) -> 0 | AZ24: =IF(ABS(AJ24)>تنظیمات!$B$10,1,0) -> 0 | BA24: =IF(AND(OR(AD24="رایگان/VIP",AD24="جانباز"),AF24="خیر"),1,0) -> 0 | BB24: =IF(AE24="",0,IF(COUNTIF($AE$2:$AE$1001,AE24)>1,1,0)) -> 0 | BC24: =IF(AND(H24="",I24>تنظیمات!$B$12*60,AM24="خالی"),1,0) -> 0 | BD24: =IF(AND(AP24="بله",I24<تنظیمات!$B$14,AO24="خیر"),1,0) -> 0 | BE24: =IF(AN24="خیر",1,0) -> 0 | BF24: =IF(AND(AD24="فیش مفقودی",AQ24="بله",I24>تنظیمات!$B$12*60),1,0) -> 0 | BG24: =IF(AND(AK24>تنظیمات!$B$11,AL24="بله"),1,0) -> 0 | BH24: =MIN(100,AR24*تنظیمات!$B$21+AS24*تنظیمات!$B$22+AT24*تنظیمات!$B$23+AU24*تنظیمات!$B$24+AV24*تنظیمات!$B$25+AW24*تنظیمات!$B$26+AX24*تنظیمات!$B$27+AY24*تنظیمات!$B$28+AZ24*تنظیمات!$B$29+BA24*تنظیمات!$B$30+BB24*تنظیمات!$B$31+BC24*تنظیمات!$B$32+BD24*تنظیمات!$B$33+BE24*تنظیمات!$B$34+BF24*تنظیمات!$B$35+BG24*تنظیمات!$B$36) -> 0 | BI24: =IF(BH24>=60,"بحرانی",IF(BH24>=30,"مشکوک",IF(BH24>0,"هشدار","عادی"))) -> عادی | BJ24: عادی
A25: EV-00024 | B25: 32ا228-38 | D25: پژو 206 | E25: سفید | F25: اقتصادی | G25: 46281.112 | H25: 46281.386 | I25: =IF(H25="",ROUND((تنظیمات!$B$7-G25)*1440,0),ROUND((H25-G25)*1440,0)) -> 395 | J25: E2 | K25: X1 | L25: 0.994 | M25: 0.884 | N25: خیر | O25: OP-01 | P25: صبح | Q25: 46281 | R25: TK-260916-00024 | S25: ابطال و بازصدور | T25: 46281.379 | U25: 1 | V25: 1 | W25: 6.1 | X25: خیر | Y25: عادی | Z25: پوز | AA25: T-1001 | AB25: 316096015175 | AC25: 46281.385 | AD25: عادی | AF25: =IF(COUNTIF(لیست_سفید!$A$2:$A$21,B25)>0,"بله","خیر") -> خیر | AG25: =IF(H25="","",IF(AD25="فیش مفقودی",تنظیمات!$B$6,(INT(I25/1440)*تنظیمات!$B$5+IF(MOD(I25,1440)<=تنظیمات!$B$2,0,MIN(تنظیمات!$B$5,تنظیمات!$B$3+MAX(0,ROUNDUP((MOD(I25,1440)-60)/60,0))*تنظیمات!$B$4)))*INDEX(تعرفه!$B$2:$B$7,MATCH(AD25,تعرفه!$A$2:$A$7,0)))) -> 104000 | AH25: 104000 | AI25: =IF(AG25="","",AH25-AG25) -> 0 | AJ25: 0 | AK25: 0 | AL25: خیر | AN25: بله | AO25: بله | AP25: خیر | AR25: =IF(AND(T25<>"",H25<>""),IF(AND((T25-H25)*86400>=0,(T25-H25)*86400<تنظیمات!$B$13),1,0),0) -> 0 | AS25: =IF(Z25="پوز",IF(OR(AB25="",COUNTIF(پوزها!$A$2:$A$5,AA25)=0),1,0),0) -> 0 | AT25: =IF(AI25="",0,IF(AI25>0,1,0)) -> 0 | AU25: =IF(AI25="",0,IF(AI25<0,1,0)) -> 0 | AV25: =IF(U25>V25,1,0) -> 0 | AW25: =IF(OR(W25>تنظیمات!$B$8,X25="بله"),1,0) -> 0 | AX25: =IF(AND(N25="بله",L25>تنظیمات!$B$9),1,0) -> 0 | AY25: =IF(Y25="معکوس",1,0) -> 0 | AZ25: =IF(ABS(AJ25)>تنظیمات!$B$10,1,0) -> 0 | BA25: =IF(AND(OR(AD25="رایگان/VIP",AD25="جانباز"),AF25="خیر"),1,0) -> 0 | BB25: =IF(AE25="",0,IF(COUNTIF($AE$2:$AE$1001,AE25)>1,1,0)) -> 0 | BC25: =IF(AND(H25="",I25>تنظیمات!$B$12*60,AM25="خالی"),1,0) -> 0 | BD25: =IF(AND(AP25="بله",I25<تنظیمات!$B$14,AO25="خیر"),1,0) -> 0 | BE25: =IF(AN25="خیر",1,0) -> 0 | BF25: =IF(AND(AD25="فیش مفقودی",AQ25="بله",I25>تنظیمات!$B$12*60),1,0) -> 0 | BG25: =IF(AND(AK25>تنظیمات!$B$11,AL25="بله"),1,0) -> 0 | BH25: =MIN(100,AR25*تنظیمات!$B$21+AS25*تنظیمات!$B$22+AT25*تنظیمات!$B$23+AU25*تنظیمات!$B$24+AV25*تنظیمات!$B$25+AW25*تنظیمات!$B$26+AX25*تنظیمات!$B$27+AY25*تنظیمات!$B$28+AZ25*تنظیمات!$B$29+BA25*تنظیمات!$B$30+BB25*تنظیمات!$B$31+BC25*تنظیمات!$B$32+BD25*تنظیمات!$B$33+BE25*تنظیمات!$B$34+BF25*تنظیمات!$B$35+BG25*تنظیمات!$B$36) -> 0 | BI25: =IF(BH25>=60,"بحرانی",IF(BH25>=30,"مشکوک",IF(BH25>0,"هشدار","عادی"))) -> عادی | BJ25: عادی
A26: EV-00025 | B26: 19ط624-47 | D26: وانت نیسان | E26: مشکی | F26: اقتصادی | G26: 46281.113 | H26: 46281.441 | I26: =IF(H26="",ROUND((تنظیمات!$B$7-G26)*1440,0),ROUND((H26-G26)*1440,0)) -> 472 | J26: E1 | K26: X1 | L26: 0.908 | M26: 0.959 | N26: خیر | O26: OP-01 | P26: صبح | Q26: 46281 | R26: TK-260916-00025 | S26: تسویه‌شده | U26: 1 | V26: 1 | W26: 3.3 | X26: خیر | Y26: عادی | Z26: پوز | AA26: T-1001 | AB26: 855422751439 | AC26: 46281.441 | AD26: عادی | AF26: =IF(COUNTIF(لیست_سفید!$A$2:$A$21,B26)>0,"بله","خیر") -> خیر | AG26: =IF(H26="","",IF(AD26="فیش مفقودی",تنظیمات!$B$6,(INT(I26/1440)*تنظیمات!$B$5+IF(MOD(I26,1440)<=تنظیمات!$B$2,0,MIN(تنظیمات!$B$5,تنظیمات!$B$3+MAX(0,ROUNDUP((MOD(I26,1440)-60)/60,0))*تنظیمات!$B$4)))*INDEX(تعرفه!$B$2:$B$7,MATCH(AD26,تعرفه!$A$2:$A$7,0)))) -> 118000 | AH26: 118000 | AI26: =IF(AG26="","",AH26-AG26) -> 0 | AJ26: -2 | AK26: 0 | AL26: خیر | AN26: بله | AO26: بله | AP26: خیر | AR26: =IF(AND(T26<>"",H26<>""),IF(AND((T26-H26)*86400>=0,(T26-H26)*86400<تنظیمات!$B$13),1,0),0) -> 0 | AS26: =IF(Z26="پوز",IF(OR(AB26="",COUNTIF(پوزها!$A$2:$A$5,AA26)=0),1,0),0) -> 0 | AT26: =IF(AI26="",0,IF(AI26>0,1,0)) -> 0 | AU26: =IF(AI26="",0,IF(AI26<0,1,0)) -> 0 | AV26: =IF(U26>V26,1,0) -> 0 | AW26: =IF(OR(W26>تنظیمات!$B$8,X26="بله"),1,0) -> 0 | AX26: =IF(AND(N26="بله",L26>تنظیمات!$B$9),1,0) -> 0 | AY26: =IF(Y26="معکوس",1,0) -> 0 | AZ26: =IF(ABS(AJ26)>تنظیمات!$B$10,1,0) -> 0 | BA26: =IF(AND(OR(AD26="رایگان/VIP",AD26="جانباز"),AF26="خیر"),1,0) -> 0 | BB26: =IF(AE26="",0,IF(COUNTIF($AE$2:$AE$1001,AE26)>1,1,0)) -> 0 | BC26: =IF(AND(H26="",I26>تنظیمات!$B$12*60,AM26="خالی"),1,0) -> 0 | BD26: =IF(AND(AP26="بله",I26<تنظیمات!$B$14,AO26="خیر"),1,0) -> 0 | BE26: =IF(AN26="خیر",1,0) -> 0 | BF26: =IF(AND(AD26="فیش مفقودی",AQ26="بله",I26>تنظیمات!$B$12*60),1,0) -> 0 | BG26: =IF(AND(AK26>تنظیمات!$B$11,AL26="بله"),1,0) -> 0 | BH26: =MIN(100,AR26*تنظیمات!$B$21+AS26*تنظیمات!$B$22+AT26*تنظیمات!$B$23+AU26*تنظیمات!$B$24+AV26*تنظیمات!$B$25+AW26*تنظیمات!$B$26+AX26*تنظیمات!$B$27+AY26*تنظیمات!$B$28+AZ26*تنظیمات!$B$29+BA26*تنظیمات!$B$30+BB26*تنظیمات!$B$31+BC26*تنظیمات!$B$32+BD26*تنظیمات!$B$33+BE26*تنظیمات!$B$34+BF26*تنظیمات!$B$35+BG26*تنظیمات!$B$36) -> 0 | BI26: =IF(BH26>=60,"بحرانی",IF(BH26>=30,"مشکوک",IF(BH26>0,"هشدار","عادی"))) -> عادی | BJ26: عادی
A27: EV-00026 | B27: 63و350-15 | D27: لکسوس RX | E27: قرمز | F27: لوکس | G27: 46281.158 | H27: 46281.324 | I27: =IF(H27="",ROUND((تنظیمات!$B$7-G27)*1440,0),ROUND((H27-G27)*1440,0)) -> 238 | J27: E2 | K27: X1 | L27: 0.995 | M27: 0.918 | N27: خیر | O27: OP-01 | P27: صبح | Q27: 46281 | R27: TK-260916-00026 | S27: تسویه‌شده | U27: 1 | V27: 1 | W27: 3.7 | X27: خیر | Y27: عادی | Z27: پوز | AA27: T-1001 | AB27: 940960176085 | AC27: 46281.323 | AD27: عادی | AF27: =IF(COUNTIF(لیست_سفید!$A$2:$A$21,B27)>0,"بله","خیر") -> خیر | AG27: =IF(H27="","",IF(AD27="فیش مفقودی",تنظیمات!$B$6,(INT(I27/1440)*تنظیمات!$B$5+IF(MOD(I27,1440)<=تنظیمات!$B$2,0,MIN(تنظیمات!$B$5,تنظیمات!$B$3+MAX(0,ROUNDUP((MOD(I27,1440)-60)/60,0))*تنظیمات!$B$4)))*INDEX(تعرفه!$B$2:$B$7,MATCH(AD27,تعرفه!$A$2:$A$7,0)))) -> 62000 | AH27: 62000 | AI27: =IF(AG27="","",AH27-AG27) -> 0 | AJ27: -5 | AK27: 0 | AL27: خیر | AN27: بله | AO27: بله | AP27: خیر | AR27: =IF(AND(T27<>"",H27<>""),IF(AND((T27-H27)*86400>=0,(T27-H27)*86400<تنظیمات!$B$13),1,0),0) -> 0 | AS27: =IF(Z27="پوز",IF(OR(AB27="",COUNTIF(پوزها!$A$2:$A$5,AA27)=0),1,0),0) -> 0 | AT27: =IF(AI27="",0,IF(AI27>0,1,0)) -> 0 | AU27: =IF(AI27="",0,IF(AI27<0,1,0)) -> 0 | AV27: =IF(U27>V27,1,0) -> 0 | AW27: =IF(OR(W27>تنظیمات!$B$8,X27="بله"),1,0) -> 0 | AX27: =IF(AND(N27="بله",L27>تنظیمات!$B$9),1,0) -> 0 | AY27: =IF(Y27="معکوس",1,0) -> 0 | AZ27: =IF(ABS(AJ27)>تنظیمات!$B$10,1,0) -> 0 | BA27: =IF(AND(OR(AD27="رایگان/VIP",AD27="جانباز"),AF27="خیر"),1,0) -> 0 | BB27: =IF(AE27="",0,IF(COUNTIF($AE$2:$AE$1001,AE27)>1,1,0)) -> 0 | BC27: =IF(AND(H27="",I27>تنظیمات!$B$12*60,AM27="خالی"),1,0) -> 0 | BD27: =IF(AND(AP27="بله",I27<تنظیمات!$B$14,AO27="خیر"),1,0) -> 0 | BE27: =IF(AN27="خیر",1,0) -> 0 | BF27: =IF(AND(AD27="فیش مفقودی",AQ27="بله",I27>تنظیمات!$B$12*60),1,0) -> 0 | BG27: =IF(AND(AK27>تنظیمات!$B$11,AL27="بله"),1,0) -> 0 | BH27: =MIN(100,AR27*تنظیمات!$B$21+AS27*تنظیمات!$B$22+AT27*تنظیمات!$B$23+AU27*تنظیمات!$B$24+AV27*تنظیمات!$B$25+AW27*تنظیمات!$B$26+AX27*تنظیمات!$B$27+AY27*تنظیمات!$B$28+AZ27*تنظیمات!$B$29+BA27*تنظیمات!$B$30+BB27*تنظیمات!$B$31+BC27*تنظیمات!$B$32+BD27*تنظیمات!$B$33+BE27*تنظیمات!$B$34+BF27*تنظیمات!$B$35+BG27*تنظیمات!$B$36) -> 0 | BI27: =IF(BH27>=60,"بحرانی",IF(BH27>=30,"مشکوک",IF(BH27>0,"هشدار","عادی"))) -> عادی | BJ27: عادی
A28: EV-00027 | B28: 18پ924-25 | D28: لکسوس RX | E28: خاکستری | F28: لوکس | G28: 46281.164 | H28: 46281.489 | I28: =IF(H28="",ROUND((تنظیمات!$B$7-G28)*1440,0),ROUND((H28-G28)*1440,0)) -> 468 | J28: E1 | K28: X1 | L28: 0.914 | M28: 0.944 | N28: خیر | O28: OP-01 | P28: صبح | Q28: 46281 | R28: TK-260916-00027 | S28: تسویه‌شده | U28: 1 | V28: 1 | W28: 5.2 | X28: خیر | Y28: عادی | Z28: معاف | AD28: رایگان/VIP | AF28: =IF(COUNTIF(لیست_سفید!$A$2:$A$21,B28)>0,"بله","خیر") -> بله | AG28: =IF(H28="","",IF(AD28="فیش مفقودی",تنظیمات!$B$6,(INT(I28/1440)*تنظیمات!$B$5+IF(MOD(I28,1440)<=تنظیمات!$B$2,0,MIN(تنظیمات!$B$5,تنظیمات!$B$3+MAX(0,ROUNDUP((MOD(I28,1440)-60)/60,0))*تنظیمات!$B$4)))*INDEX(تعرفه!$B$2:$B$7,MATCH(AD28,تعرفه!$A$2:$A$7,0)))) -> 0 | AH28: 0 | AI28: =IF(AG28="","",AH28-AG28) -> 0 | AJ28: 1 | AK28: 0 | AL28: خیر | AN28: بله | AO28: بله | AP28: خیر | AR28: =IF(AND(T28<>"",H28<>""),IF(AND((T28-H28)*86400>=0,(T28-H28)*86400<تنظیمات!$B$13),1,0),0) -> 0 | AS28: =IF(Z28="پوز",IF(OR(AB28="",COUNTIF(پوزها!$A$2:$A$5,AA28)=0),1,0),0) -> 0 | AT28: =IF(AI28="",0,IF(AI28>0,1,0)) -> 0 | AU28: =IF(AI28="",0,IF(AI28<0,1,0)) -> 0 | AV28: =IF(U28>V28,1,0) -> 0 | AW28: =IF(OR(W28>تنظیمات!$B$8,X28="بله"),1,0) -> 0 | AX28: =IF(AND(N28="بله",L28>تنظیمات!$B$9),1,0) -> 0 | AY28: =IF(Y28="معکوس",1,0) -> 0 | AZ28: =IF(ABS(AJ28)>تنظیمات!$B$10,1,0) -> 0 | BA28: =IF(AND(OR(AD28="رایگان/VIP",AD28="جانباز"),AF28="خیر"),1,0) -> 0 | BB28: =IF(AE28="",0,IF(COUNTIF($AE$2:$AE$1001,AE28)>1,1,0)) -> 0 | BC28: =IF(AND(H28="",I28>تنظیمات!$B$12*60,AM28="خالی"),1,0) -> 0 | BD28: =IF(AND(AP28="بله",I28<تنظیمات!$B$14,AO28="خیر"),1,0) -> 0 | BE28: =IF(AN28="خیر",1,0) -> 0 | BF28: =IF(AND(AD28="فیش مفقودی",AQ28="بله",I28>تنظیمات!$B$12*60),1,0) -> 0 | BG28: =IF(AND(AK28>تنظیمات!$B$11,AL28="بله"),1,0) -> 0 | BH28: =MIN(100,AR28*تنظیمات!$B$21+AS28*تنظیمات!$B$22+AT28*تنظیمات!$B$23+AU28*تنظیمات!$B$24+AV28*تنظیمات!$B$25+AW28*تنظیمات!$B$26+AX28*تنظیمات!$B$27+AY28*تنظیمات!$B$28+AZ28*تنظیمات!$B$29+BA28*تنظیمات!$B$30+BB28*تنظیمات!$B$31+BC28*تنظیمات!$B$32+BD28*تنظیمات!$B$33+BE28*تنظیمات!$B$34+BF28*تنظیمات!$B$35+BG28*تنظیمات!$B$36) -> 0 | BI28: =IF(BH28>=60,"بحرانی",IF(BH28>=30,"مشکوک",IF(BH28>0,"هشدار","عادی"))) -> عادی | BJ28: عادی
